[2020-07-03 08:44:23 +0800] [1099] [INFO] Starting gunicorn 20.0.4
[2020-07-03 08:44:23 +0800] [1099] [INFO] Listening at: http://0.0.0.0:8002 (1099)
[2020-07-03 08:44:23 +0800] [1099] [INFO] Using worker: sync
[2020-07-03 08:44:23 +0800] [1128] [INFO] Booting worker with pid: 1128
[2020-07-03 08:44:23 +0800] [1130] [INFO] Booting worker with pid: 1130
[2020-07-03 08:46:39 +0800] [1099] [INFO] Handling signal: term
[2020-07-03 08:46:39 +0800] [1130] [INFO] Worker exiting (pid: 1130)
[2020-07-03 08:46:39 +0800] [1128] [INFO] Worker exiting (pid: 1128)
[2020-07-03 08:46:39 +0800] [1099] [INFO] Shutting down: Master
[2020-07-03 08:46:41 +0800] [1945] [INFO] Starting gunicorn 20.0.4
[2020-07-03 08:46:41 +0800] [1945] [INFO] Listening at: http://0.0.0.0:8002 (1945)
[2020-07-03 08:46:41 +0800] [1945] [INFO] Using worker: sync
[2020-07-03 08:46:41 +0800] [1950] [INFO] Booting worker with pid: 1950
[2020-07-03 08:46:41 +0800] [1955] [INFO] Booting worker with pid: 1955
[2020-07-03 08:46:42 +0800] [1956] [INFO] Booting worker with pid: 1956
[2020-07-03 08:46:42 +0800] [1957] [INFO] Booting worker with pid: 1957
[2020-07-03 09:09:13 +0800] [1945] [INFO] Handling signal: term
/home/fms/project/venv/lib/python3.7/site-packages/pymysql/cursors.py:170: Warning: (1366, "Incorrect string value: '\\xD6\\xD0\\xB9\\xFA\\xB1\\xEA...' for column 'VARIABLE_VALUE' at row 480")
  result = self._query(query)
[2020-07-03 09:09:13 +0800] [1957] [INFO] Worker exiting (pid: 1957)
[2020-07-03 09:09:13 +0800] [1956] [INFO] Worker exiting (pid: 1956)
[2020-07-03 09:09:13 +0800] [1950] [INFO] Worker exiting (pid: 1950)
[2020-07-03 09:09:13 +0800] [1955] [INFO] Worker exiting (pid: 1955)
[2020-07-03 09:09:13 +0800] [1945] [INFO] Shutting down: Master
[2020-07-03 09:09:15 +0800] [2238] [INFO] Starting gunicorn 20.0.4
[2020-07-03 09:09:15 +0800] [2238] [INFO] Listening at: http://0.0.0.0:8002 (2238)
[2020-07-03 09:09:15 +0800] [2238] [INFO] Using worker: sync
[2020-07-03 09:09:15 +0800] [2242] [INFO] Booting worker with pid: 2242
[2020-07-03 09:09:15 +0800] [2245] [INFO] Booting worker with pid: 2245
[2020-07-03 09:09:15 +0800] [2246] [INFO] Booting worker with pid: 2246
[2020-07-03 09:09:16 +0800] [2249] [INFO] Booting worker with pid: 2249
/home/fms/project/venv/lib/python3.7/site-packages/pymysql/cursors.py:170: Warning: (1366, "Incorrect string value: '\\xD6\\xD0\\xB9\\xFA\\xB1\\xEA...' for column 'VARIABLE_VALUE' at row 480")
  result = self._query(query)
[2020-07-03 09:42:23,568] ERROR in app: Exception on /work/up/ [POST]
Traceback (most recent call last):
  File "/home/fms/project/venv/lib/python3.7/site-packages/sqlalchemy/engine/base.py", line 1278, in _execute_context
    cursor, statement, parameters, context
  File "/home/fms/project/venv/lib/python3.7/site-packages/sqlalchemy/engine/default.py", line 593, in do_execute
    cursor.execute(statement, parameters)
  File "/home/fms/project/venv/lib/python3.7/site-packages/pymysql/cursors.py", line 170, in execute
    result = self._query(query)
  File "/home/fms/project/venv/lib/python3.7/site-packages/pymysql/cursors.py", line 328, in _query
    conn.query(q)
  File "/home/fms/project/venv/lib/python3.7/site-packages/pymysql/connections.py", line 517, in query
    self._affected_rows = self._read_query_result(unbuffered=unbuffered)
  File "/home/fms/project/venv/lib/python3.7/site-packages/pymysql/connections.py", line 732, in _read_query_result
    result.read()
  File "/home/fms/project/venv/lib/python3.7/site-packages/pymysql/connections.py", line 1075, in read
    first_packet = self.connection._read_packet()
  File "/home/fms/project/venv/lib/python3.7/site-packages/pymysql/connections.py", line 657, in _read_packet
    packet_header = self._read_bytes(4)
  File "/home/fms/project/venv/lib/python3.7/site-packages/pymysql/connections.py", line 707, in _read_bytes
    CR.CR_SERVER_LOST, "Lost connection to MySQL server during query")
pymysql.err.OperationalError: (2013, 'Lost connection to MySQL server during query')

The above exception was the direct cause of the following exception:

Traceback (most recent call last):
  File "/home/fms/project/venv/lib/python3.7/site-packages/flask/app.py", line 2447, in wsgi_app
    response = self.full_dispatch_request()
  File "/home/fms/project/venv/lib/python3.7/site-packages/flask/app.py", line 1952, in full_dispatch_request
    rv = self.handle_user_exception(e)
  File "/home/fms/project/venv/lib/python3.7/site-packages/flask/app.py", line 1821, in handle_user_exception
    reraise(exc_type, exc_value, tb)
  File "/home/fms/project/venv/lib/python3.7/site-packages/flask/_compat.py", line 39, in reraise
    raise value
  File "/home/fms/project/venv/lib/python3.7/site-packages/flask/app.py", line 1950, in full_dispatch_request
    rv = self.dispatch_request()
  File "/home/fms/project/venv/lib/python3.7/site-packages/flask/app.py", line 1936, in dispatch_request
    return self.view_functions[rule.endpoint](**req.view_args)
  File "/home/fms/project/work2database/app.py", line 334, in update_work
    ori_content=ori_content))
  File "/home/fms/project/venv/lib/python3.7/site-packages/sqlalchemy/orm/session.py", line 1292, in execute
    clause, params or {}
  File "/home/fms/project/venv/lib/python3.7/site-packages/sqlalchemy/engine/base.py", line 1014, in execute
    return meth(self, multiparams, params)
  File "/home/fms/project/venv/lib/python3.7/site-packages/sqlalchemy/sql/elements.py", line 298, in _execute_on_connection
    return connection._execute_clauseelement(self, multiparams, params)
  File "/home/fms/project/venv/lib/python3.7/site-packages/sqlalchemy/engine/base.py", line 1133, in _execute_clauseelement
    distilled_params,
  File "/home/fms/project/venv/lib/python3.7/site-packages/sqlalchemy/engine/base.py", line 1318, in _execute_context
    e, statement, parameters, cursor, context
  File "/home/fms/project/venv/lib/python3.7/site-packages/sqlalchemy/engine/base.py", line 1512, in _handle_dbapi_exception
    sqlalchemy_exception, with_traceback=exc_info[2], from_=e
  File "/home/fms/project/venv/lib/python3.7/site-packages/sqlalchemy/util/compat.py", line 178, in raise_
    raise exception
  File "/home/fms/project/venv/lib/python3.7/site-packages/sqlalchemy/engine/base.py", line 1278, in _execute_context
    cursor, statement, parameters, context
  File "/home/fms/project/venv/lib/python3.7/site-packages/sqlalchemy/engine/default.py", line 593, in do_execute
    cursor.execute(statement, parameters)
  File "/home/fms/project/venv/lib/python3.7/site-packages/pymysql/cursors.py", line 170, in execute
    result = self._query(query)
  File "/home/fms/project/venv/lib/python3.7/site-packages/pymysql/cursors.py", line 328, in _query
    conn.query(q)
  File "/home/fms/project/venv/lib/python3.7/site-packages/pymysql/connections.py", line 517, in query
    self._affected_rows = self._read_query_result(unbuffered=unbuffered)
  File "/home/fms/project/venv/lib/python3.7/site-packages/pymysql/connections.py", line 732, in _read_query_result
    result.read()
  File "/home/fms/project/venv/lib/python3.7/site-packages/pymysql/connections.py", line 1075, in read
    first_packet = self.connection._read_packet()
  File "/home/fms/project/venv/lib/python3.7/site-packages/pymysql/connections.py", line 657, in _read_packet
    packet_header = self._read_bytes(4)
  File "/home/fms/project/venv/lib/python3.7/site-packages/pymysql/connections.py", line 707, in _read_bytes
    CR.CR_SERVER_LOST, "Lost connection to MySQL server during query")
sqlalchemy.exc.OperationalError: (pymysql.err.OperationalError) (2013, 'Lost connection to MySQL server during query')
[SQL: UPDATE `工作周报` SET `周` = '27' ,`开始日期` = '2020-06-30' ,`结束日期` = '9999-09-09' ,`工作类别` = '安排的工作' ,`工作内容` = '电信自缴费电费台账填报系统开发。' , `当前状态` = '进行中' WHERE `姓名` = '田中玉' AND `开始日期` = '2020-06-30' AND `工作类别` = '安排的工作' AND  `工作内容` = '电信自缴费电费台账填报系统开发。']
(Background on this error at: http://sqlalche.me/e/13/e3q8)
/home/fms/project/venv/lib/python3.7/site-packages/pymysql/cursors.py:170: Warning: (1366, "Incorrect string value: '\\xD6\\xD0\\xB9\\xFA\\xB1\\xEA...' for column 'VARIABLE_VALUE' at row 480")
  result = self._query(query)
[2020-07-03 09:42:32,440] ERROR in app: Exception on /work/tzy [GET]
Traceback (most recent call last):
  File "/home/fms/project/venv/lib/python3.7/site-packages/sqlalchemy/engine/base.py", line 1278, in _execute_context
    cursor, statement, parameters, context
  File "/home/fms/project/venv/lib/python3.7/site-packages/sqlalchemy/engine/default.py", line 593, in do_execute
    cursor.execute(statement, parameters)
  File "/home/fms/project/venv/lib/python3.7/site-packages/pymysql/cursors.py", line 170, in execute
    result = self._query(query)
  File "/home/fms/project/venv/lib/python3.7/site-packages/pymysql/cursors.py", line 328, in _query
    conn.query(q)
  File "/home/fms/project/venv/lib/python3.7/site-packages/pymysql/connections.py", line 517, in query
    self._affected_rows = self._read_query_result(unbuffered=unbuffered)
  File "/home/fms/project/venv/lib/python3.7/site-packages/pymysql/connections.py", line 732, in _read_query_result
    result.read()
  File "/home/fms/project/venv/lib/python3.7/site-packages/pymysql/connections.py", line 1075, in read
    first_packet = self.connection._read_packet()
  File "/home/fms/project/venv/lib/python3.7/site-packages/pymysql/connections.py", line 657, in _read_packet
    packet_header = self._read_bytes(4)
  File "/home/fms/project/venv/lib/python3.7/site-packages/pymysql/connections.py", line 707, in _read_bytes
    CR.CR_SERVER_LOST, "Lost connection to MySQL server during query")
pymysql.err.OperationalError: (2013, 'Lost connection to MySQL server during query')

The above exception was the direct cause of the following exception:

Traceback (most recent call last):
  File "/home/fms/project/venv/lib/python3.7/site-packages/flask/app.py", line 2447, in wsgi_app
    response = self.full_dispatch_request()
  File "/home/fms/project/venv/lib/python3.7/site-packages/flask/app.py", line 1952, in full_dispatch_request
    rv = self.handle_user_exception(e)
  File "/home/fms/project/venv/lib/python3.7/site-packages/flask/app.py", line 1821, in handle_user_exception
    reraise(exc_type, exc_value, tb)
  File "/home/fms/project/venv/lib/python3.7/site-packages/flask/_compat.py", line 39, in reraise
    raise value
  File "/home/fms/project/venv/lib/python3.7/site-packages/flask/app.py", line 1950, in full_dispatch_request
    rv = self.dispatch_request()
  File "/home/fms/project/venv/lib/python3.7/site-packages/flask/app.py", line 1936, in dispatch_request
    return self.view_functions[rule.endpoint](**req.view_args)
  File "/home/fms/project/work2database/app.py", line 213, in work2datebase
    wk=week))
  File "/home/fms/project/venv/lib/python3.7/site-packages/sqlalchemy/orm/session.py", line 1292, in execute
    clause, params or {}
  File "/home/fms/project/venv/lib/python3.7/site-packages/sqlalchemy/engine/base.py", line 1014, in execute
    return meth(self, multiparams, params)
  File "/home/fms/project/venv/lib/python3.7/site-packages/sqlalchemy/sql/elements.py", line 298, in _execute_on_connection
    return connection._execute_clauseelement(self, multiparams, params)
  File "/home/fms/project/venv/lib/python3.7/site-packages/sqlalchemy/engine/base.py", line 1133, in _execute_clauseelement
    distilled_params,
  File "/home/fms/project/venv/lib/python3.7/site-packages/sqlalchemy/engine/base.py", line 1318, in _execute_context
    e, statement, parameters, cursor, context
  File "/home/fms/project/venv/lib/python3.7/site-packages/sqlalchemy/engine/base.py", line 1512, in _handle_dbapi_exception
    sqlalchemy_exception, with_traceback=exc_info[2], from_=e
  File "/home/fms/project/venv/lib/python3.7/site-packages/sqlalchemy/util/compat.py", line 178, in raise_
    raise exception
  File "/home/fms/project/venv/lib/python3.7/site-packages/sqlalchemy/engine/base.py", line 1278, in _execute_context
    cursor, statement, parameters, context
  File "/home/fms/project/venv/lib/python3.7/site-packages/sqlalchemy/engine/default.py", line 593, in do_execute
    cursor.execute(statement, parameters)
  File "/home/fms/project/venv/lib/python3.7/site-packages/pymysql/cursors.py", line 170, in execute
    result = self._query(query)
  File "/home/fms/project/venv/lib/python3.7/site-packages/pymysql/cursors.py", line 328, in _query
    conn.query(q)
  File "/home/fms/project/venv/lib/python3.7/site-packages/pymysql/connections.py", line 517, in query
    self._affected_rows = self._read_query_result(unbuffered=unbuffered)
  File "/home/fms/project/venv/lib/python3.7/site-packages/pymysql/connections.py", line 732, in _read_query_result
    result.read()
  File "/home/fms/project/venv/lib/python3.7/site-packages/pymysql/connections.py", line 1075, in read
    first_packet = self.connection._read_packet()
  File "/home/fms/project/venv/lib/python3.7/site-packages/pymysql/connections.py", line 657, in _read_packet
    packet_header = self._read_bytes(4)
  File "/home/fms/project/venv/lib/python3.7/site-packages/pymysql/connections.py", line 707, in _read_bytes
    CR.CR_SERVER_LOST, "Lost connection to MySQL server during query")
sqlalchemy.exc.OperationalError: (pymysql.err.OperationalError) (2013, 'Lost connection to MySQL server during query')
[SQL: SELECT * from `工作周报` where `姓名` = '田中玉' and `周` = 27 and `工作类别` = '安排的工作']
(Background on this error at: http://sqlalche.me/e/13/e3q8)
/home/fms/project/venv/lib/python3.7/site-packages/pymysql/cursors.py:170: Warning: (1366, "Incorrect string value: '\\xD6\\xD0\\xB9\\xFA\\xB1\\xEA...' for column 'VARIABLE_VALUE' at row 480")
  result = self._query(query)
[2020-07-03 09:42:35,200] ERROR in app: Exception on /work/tzy [GET]
Traceback (most recent call last):
  File "/home/fms/project/venv/lib/python3.7/site-packages/sqlalchemy/engine/base.py", line 1278, in _execute_context
    cursor, statement, parameters, context
  File "/home/fms/project/venv/lib/python3.7/site-packages/sqlalchemy/engine/default.py", line 593, in do_execute
    cursor.execute(statement, parameters)
  File "/home/fms/project/venv/lib/python3.7/site-packages/pymysql/cursors.py", line 170, in execute
    result = self._query(query)
  File "/home/fms/project/venv/lib/python3.7/site-packages/pymysql/cursors.py", line 328, in _query
    conn.query(q)
  File "/home/fms/project/venv/lib/python3.7/site-packages/pymysql/connections.py", line 517, in query
    self._affected_rows = self._read_query_result(unbuffered=unbuffered)
  File "/home/fms/project/venv/lib/python3.7/site-packages/pymysql/connections.py", line 732, in _read_query_result
    result.read()
  File "/home/fms/project/venv/lib/python3.7/site-packages/pymysql/connections.py", line 1075, in read
    first_packet = self.connection._read_packet()
  File "/home/fms/project/venv/lib/python3.7/site-packages/pymysql/connections.py", line 657, in _read_packet
    packet_header = self._read_bytes(4)
  File "/home/fms/project/venv/lib/python3.7/site-packages/pymysql/connections.py", line 707, in _read_bytes
    CR.CR_SERVER_LOST, "Lost connection to MySQL server during query")
pymysql.err.OperationalError: (2013, 'Lost connection to MySQL server during query')

The above exception was the direct cause of the following exception:

Traceback (most recent call last):
  File "/home/fms/project/venv/lib/python3.7/site-packages/flask/app.py", line 2447, in wsgi_app
    response = self.full_dispatch_request()
  File "/home/fms/project/venv/lib/python3.7/site-packages/flask/app.py", line 1952, in full_dispatch_request
    rv = self.handle_user_exception(e)
  File "/home/fms/project/venv/lib/python3.7/site-packages/flask/app.py", line 1821, in handle_user_exception
    reraise(exc_type, exc_value, tb)
  File "/home/fms/project/venv/lib/python3.7/site-packages/flask/_compat.py", line 39, in reraise
    raise value
  File "/home/fms/project/venv/lib/python3.7/site-packages/flask/app.py", line 1950, in full_dispatch_request
    rv = self.dispatch_request()
  File "/home/fms/project/venv/lib/python3.7/site-packages/flask/app.py", line 1936, in dispatch_request
    return self.view_functions[rule.endpoint](**req.view_args)
  File "/home/fms/project/work2database/app.py", line 213, in work2datebase
    wk=week))
  File "/home/fms/project/venv/lib/python3.7/site-packages/sqlalchemy/orm/session.py", line 1292, in execute
    clause, params or {}
  File "/home/fms/project/venv/lib/python3.7/site-packages/sqlalchemy/engine/base.py", line 1014, in execute
    return meth(self, multiparams, params)
  File "/home/fms/project/venv/lib/python3.7/site-packages/sqlalchemy/sql/elements.py", line 298, in _execute_on_connection
    return connection._execute_clauseelement(self, multiparams, params)
  File "/home/fms/project/venv/lib/python3.7/site-packages/sqlalchemy/engine/base.py", line 1133, in _execute_clauseelement
    distilled_params,
  File "/home/fms/project/venv/lib/python3.7/site-packages/sqlalchemy/engine/base.py", line 1318, in _execute_context
    e, statement, parameters, cursor, context
  File "/home/fms/project/venv/lib/python3.7/site-packages/sqlalchemy/engine/base.py", line 1512, in _handle_dbapi_exception
    sqlalchemy_exception, with_traceback=exc_info[2], from_=e
  File "/home/fms/project/venv/lib/python3.7/site-packages/sqlalchemy/util/compat.py", line 178, in raise_
    raise exception
  File "/home/fms/project/venv/lib/python3.7/site-packages/sqlalchemy/engine/base.py", line 1278, in _execute_context
    cursor, statement, parameters, context
  File "/home/fms/project/venv/lib/python3.7/site-packages/sqlalchemy/engine/default.py", line 593, in do_execute
    cursor.execute(statement, parameters)
  File "/home/fms/project/venv/lib/python3.7/site-packages/pymysql/cursors.py", line 170, in execute
    result = self._query(query)
  File "/home/fms/project/venv/lib/python3.7/site-packages/pymysql/cursors.py", line 328, in _query
    conn.query(q)
  File "/home/fms/project/venv/lib/python3.7/site-packages/pymysql/connections.py", line 517, in query
    self._affected_rows = self._read_query_result(unbuffered=unbuffered)
  File "/home/fms/project/venv/lib/python3.7/site-packages/pymysql/connections.py", line 732, in _read_query_result
    result.read()
  File "/home/fms/project/venv/lib/python3.7/site-packages/pymysql/connections.py", line 1075, in read
    first_packet = self.connection._read_packet()
  File "/home/fms/project/venv/lib/python3.7/site-packages/pymysql/connections.py", line 657, in _read_packet
    packet_header = self._read_bytes(4)
  File "/home/fms/project/venv/lib/python3.7/site-packages/pymysql/connections.py", line 707, in _read_bytes
    CR.CR_SERVER_LOST, "Lost connection to MySQL server during query")
sqlalchemy.exc.OperationalError: (pymysql.err.OperationalError) (2013, 'Lost connection to MySQL server during query')
[SQL: SELECT * from `工作周报` where `姓名` = '田中玉' and `周` = 27 and `工作类别` = '安排的工作']
(Background on this error at: http://sqlalche.me/e/13/e3q8)
/home/fms/project/venv/lib/python3.7/site-packages/pymysql/cursors.py:170: Warning: (1366, "Incorrect string value: '\\xD6\\xD0\\xB9\\xFA\\xB1\\xEA...' for column 'VARIABLE_VALUE' at row 480")
  result = self._query(query)
[2020-07-03 09:42:38,664] ERROR in app: Exception on /work/ [GET]
Traceback (most recent call last):
  File "/home/fms/project/venv/lib/python3.7/site-packages/sqlalchemy/engine/base.py", line 1278, in _execute_context
    cursor, statement, parameters, context
  File "/home/fms/project/venv/lib/python3.7/site-packages/sqlalchemy/engine/default.py", line 593, in do_execute
    cursor.execute(statement, parameters)
  File "/home/fms/project/venv/lib/python3.7/site-packages/pymysql/cursors.py", line 170, in execute
    result = self._query(query)
  File "/home/fms/project/venv/lib/python3.7/site-packages/pymysql/cursors.py", line 328, in _query
    conn.query(q)
  File "/home/fms/project/venv/lib/python3.7/site-packages/pymysql/connections.py", line 517, in query
    self._affected_rows = self._read_query_result(unbuffered=unbuffered)
  File "/home/fms/project/venv/lib/python3.7/site-packages/pymysql/connections.py", line 732, in _read_query_result
    result.read()
  File "/home/fms/project/venv/lib/python3.7/site-packages/pymysql/connections.py", line 1075, in read
    first_packet = self.connection._read_packet()
  File "/home/fms/project/venv/lib/python3.7/site-packages/pymysql/connections.py", line 657, in _read_packet
    packet_header = self._read_bytes(4)
  File "/home/fms/project/venv/lib/python3.7/site-packages/pymysql/connections.py", line 707, in _read_bytes
    CR.CR_SERVER_LOST, "Lost connection to MySQL server during query")
pymysql.err.OperationalError: (2013, 'Lost connection to MySQL server during query')

The above exception was the direct cause of the following exception:

Traceback (most recent call last):
  File "/home/fms/project/venv/lib/python3.7/site-packages/flask/app.py", line 2447, in wsgi_app
    response = self.full_dispatch_request()
  File "/home/fms/project/venv/lib/python3.7/site-packages/flask/app.py", line 1952, in full_dispatch_request
    rv = self.handle_user_exception(e)
  File "/home/fms/project/venv/lib/python3.7/site-packages/flask/app.py", line 1821, in handle_user_exception
    reraise(exc_type, exc_value, tb)
  File "/home/fms/project/venv/lib/python3.7/site-packages/flask/_compat.py", line 39, in reraise
    raise value
  File "/home/fms/project/venv/lib/python3.7/site-packages/flask/app.py", line 1950, in full_dispatch_request
    rv = self.dispatch_request()
  File "/home/fms/project/venv/lib/python3.7/site-packages/flask/app.py", line 1936, in dispatch_request
    return self.view_functions[rule.endpoint](**req.view_args)
  File "/home/fms/project/work2database/app.py", line 121, in show_department_work
    work_data = session_work.execute("SELECT * from `工作周报` where `周` = {wk} and `工作类别` != '安排的工作' order by `姓名`,`开始日期` asc ".format(wk=week))
  File "/home/fms/project/venv/lib/python3.7/site-packages/sqlalchemy/orm/session.py", line 1292, in execute
    clause, params or {}
  File "/home/fms/project/venv/lib/python3.7/site-packages/sqlalchemy/engine/base.py", line 1014, in execute
    return meth(self, multiparams, params)
  File "/home/fms/project/venv/lib/python3.7/site-packages/sqlalchemy/sql/elements.py", line 298, in _execute_on_connection
    return connection._execute_clauseelement(self, multiparams, params)
  File "/home/fms/project/venv/lib/python3.7/site-packages/sqlalchemy/engine/base.py", line 1133, in _execute_clauseelement
    distilled_params,
  File "/home/fms/project/venv/lib/python3.7/site-packages/sqlalchemy/engine/base.py", line 1318, in _execute_context
    e, statement, parameters, cursor, context
  File "/home/fms/project/venv/lib/python3.7/site-packages/sqlalchemy/engine/base.py", line 1512, in _handle_dbapi_exception
    sqlalchemy_exception, with_traceback=exc_info[2], from_=e
  File "/home/fms/project/venv/lib/python3.7/site-packages/sqlalchemy/util/compat.py", line 178, in raise_
    raise exception
  File "/home/fms/project/venv/lib/python3.7/site-packages/sqlalchemy/engine/base.py", line 1278, in _execute_context
    cursor, statement, parameters, context
  File "/home/fms/project/venv/lib/python3.7/site-packages/sqlalchemy/engine/default.py", line 593, in do_execute
    cursor.execute(statement, parameters)
  File "/home/fms/project/venv/lib/python3.7/site-packages/pymysql/cursors.py", line 170, in execute
    result = self._query(query)
  File "/home/fms/project/venv/lib/python3.7/site-packages/pymysql/cursors.py", line 328, in _query
    conn.query(q)
  File "/home/fms/project/venv/lib/python3.7/site-packages/pymysql/connections.py", line 517, in query
    self._affected_rows = self._read_query_result(unbuffered=unbuffered)
  File "/home/fms/project/venv/lib/python3.7/site-packages/pymysql/connections.py", line 732, in _read_query_result
    result.read()
  File "/home/fms/project/venv/lib/python3.7/site-packages/pymysql/connections.py", line 1075, in read
    first_packet = self.connection._read_packet()
  File "/home/fms/project/venv/lib/python3.7/site-packages/pymysql/connections.py", line 657, in _read_packet
    packet_header = self._read_bytes(4)
  File "/home/fms/project/venv/lib/python3.7/site-packages/pymysql/connections.py", line 707, in _read_bytes
    CR.CR_SERVER_LOST, "Lost connection to MySQL server during query")
sqlalchemy.exc.OperationalError: (pymysql.err.OperationalError) (2013, 'Lost connection to MySQL server during query')
[SQL: SELECT * from `工作周报` where `周` = 27 and `工作类别` != '安排的工作' order by `姓名`,`开始日期` asc ]
(Background on this error at: http://sqlalche.me/e/13/e3q8)
[2020-07-03 09:42:42,838] ERROR in app: Exception on /work/ [GET]
Traceback (most recent call last):
  File "/home/fms/project/venv/lib/python3.7/site-packages/sqlalchemy/engine/base.py", line 1203, in _execute_context
    conn = self._revalidate_connection()
  File "/home/fms/project/venv/lib/python3.7/site-packages/sqlalchemy/engine/base.py", line 473, in _revalidate_connection
    "Can't reconnect until invalid "
sqlalchemy.exc.InvalidRequestError: Can't reconnect until invalid transaction is rolled back

The above exception was the direct cause of the following exception:

Traceback (most recent call last):
  File "/home/fms/project/venv/lib/python3.7/site-packages/flask/app.py", line 2447, in wsgi_app
    response = self.full_dispatch_request()
  File "/home/fms/project/venv/lib/python3.7/site-packages/flask/app.py", line 1952, in full_dispatch_request
    rv = self.handle_user_exception(e)
  File "/home/fms/project/venv/lib/python3.7/site-packages/flask/app.py", line 1821, in handle_user_exception
    reraise(exc_type, exc_value, tb)
  File "/home/fms/project/venv/lib/python3.7/site-packages/flask/_compat.py", line 39, in reraise
    raise value
  File "/home/fms/project/venv/lib/python3.7/site-packages/flask/app.py", line 1950, in full_dispatch_request
    rv = self.dispatch_request()
  File "/home/fms/project/venv/lib/python3.7/site-packages/flask/app.py", line 1936, in dispatch_request
    return self.view_functions[rule.endpoint](**req.view_args)
  File "/home/fms/project/work2database/app.py", line 121, in show_department_work
    work_data = session_work.execute("SELECT * from `工作周报` where `周` = {wk} and `工作类别` != '安排的工作' order by `姓名`,`开始日期` asc ".format(wk=week))
  File "/home/fms/project/venv/lib/python3.7/site-packages/sqlalchemy/orm/session.py", line 1292, in execute
    clause, params or {}
  File "/home/fms/project/venv/lib/python3.7/site-packages/sqlalchemy/engine/base.py", line 1014, in execute
    return meth(self, multiparams, params)
  File "/home/fms/project/venv/lib/python3.7/site-packages/sqlalchemy/sql/elements.py", line 298, in _execute_on_connection
    return connection._execute_clauseelement(self, multiparams, params)
  File "/home/fms/project/venv/lib/python3.7/site-packages/sqlalchemy/engine/base.py", line 1133, in _execute_clauseelement
    distilled_params,
  File "/home/fms/project/venv/lib/python3.7/site-packages/sqlalchemy/engine/base.py", line 1208, in _execute_context
    e, util.text_type(statement), parameters, None, None
  File "/home/fms/project/venv/lib/python3.7/site-packages/sqlalchemy/engine/base.py", line 1512, in _handle_dbapi_exception
    sqlalchemy_exception, with_traceback=exc_info[2], from_=e
  File "/home/fms/project/venv/lib/python3.7/site-packages/sqlalchemy/util/compat.py", line 178, in raise_
    raise exception
  File "/home/fms/project/venv/lib/python3.7/site-packages/sqlalchemy/engine/base.py", line 1203, in _execute_context
    conn = self._revalidate_connection()
  File "/home/fms/project/venv/lib/python3.7/site-packages/sqlalchemy/engine/base.py", line 473, in _revalidate_connection
    "Can't reconnect until invalid "
sqlalchemy.exc.StatementError: (sqlalchemy.exc.InvalidRequestError) Can't reconnect until invalid transaction is rolled back
[SQL: SELECT * from `工作周报` where `周` = 27 and `工作类别` != '安排的工作' order by `姓名`,`开始日期` asc ]
[parameters: [{}]]
[2020-07-03 09:42:47,766] ERROR in app: Exception on /work/tzy [GET]
Traceback (most recent call last):
  File "/home/fms/project/venv/lib/python3.7/site-packages/sqlalchemy/engine/base.py", line 1203, in _execute_context
    conn = self._revalidate_connection()
  File "/home/fms/project/venv/lib/python3.7/site-packages/sqlalchemy/engine/base.py", line 473, in _revalidate_connection
    "Can't reconnect until invalid "
sqlalchemy.exc.InvalidRequestError: Can't reconnect until invalid transaction is rolled back

The above exception was the direct cause of the following exception:

Traceback (most recent call last):
  File "/home/fms/project/venv/lib/python3.7/site-packages/flask/app.py", line 2447, in wsgi_app
    response = self.full_dispatch_request()
  File "/home/fms/project/venv/lib/python3.7/site-packages/flask/app.py", line 1952, in full_dispatch_request
    rv = self.handle_user_exception(e)
  File "/home/fms/project/venv/lib/python3.7/site-packages/flask/app.py", line 1821, in handle_user_exception
    reraise(exc_type, exc_value, tb)
  File "/home/fms/project/venv/lib/python3.7/site-packages/flask/_compat.py", line 39, in reraise
    raise value
  File "/home/fms/project/venv/lib/python3.7/site-packages/flask/app.py", line 1950, in full_dispatch_request
    rv = self.dispatch_request()
  File "/home/fms/project/venv/lib/python3.7/site-packages/flask/app.py", line 1936, in dispatch_request
    return self.view_functions[rule.endpoint](**req.view_args)
  File "/home/fms/project/work2database/app.py", line 213, in work2datebase
    wk=week))
  File "/home/fms/project/venv/lib/python3.7/site-packages/sqlalchemy/orm/session.py", line 1292, in execute
    clause, params or {}
  File "/home/fms/project/venv/lib/python3.7/site-packages/sqlalchemy/engine/base.py", line 1014, in execute
    return meth(self, multiparams, params)
  File "/home/fms/project/venv/lib/python3.7/site-packages/sqlalchemy/sql/elements.py", line 298, in _execute_on_connection
    return connection._execute_clauseelement(self, multiparams, params)
  File "/home/fms/project/venv/lib/python3.7/site-packages/sqlalchemy/engine/base.py", line 1133, in _execute_clauseelement
    distilled_params,
  File "/home/fms/project/venv/lib/python3.7/site-packages/sqlalchemy/engine/base.py", line 1208, in _execute_context
    e, util.text_type(statement), parameters, None, None
  File "/home/fms/project/venv/lib/python3.7/site-packages/sqlalchemy/engine/base.py", line 1512, in _handle_dbapi_exception
    sqlalchemy_exception, with_traceback=exc_info[2], from_=e
  File "/home/fms/project/venv/lib/python3.7/site-packages/sqlalchemy/util/compat.py", line 178, in raise_
    raise exception
  File "/home/fms/project/venv/lib/python3.7/site-packages/sqlalchemy/engine/base.py", line 1203, in _execute_context
    conn = self._revalidate_connection()
  File "/home/fms/project/venv/lib/python3.7/site-packages/sqlalchemy/engine/base.py", line 473, in _revalidate_connection
    "Can't reconnect until invalid "
sqlalchemy.exc.StatementError: (sqlalchemy.exc.InvalidRequestError) Can't reconnect until invalid transaction is rolled back
[SQL: SELECT * from `工作周报` where `姓名` = '田中玉' and `周` = 27 and `工作类别` = '安排的工作']
[parameters: [{}]]
[2020-07-03 09:43:04,134] ERROR in app: Exception on /work/tzy [GET]
Traceback (most recent call last):
  File "/home/fms/project/venv/lib/python3.7/site-packages/sqlalchemy/engine/base.py", line 1203, in _execute_context
    conn = self._revalidate_connection()
  File "/home/fms/project/venv/lib/python3.7/site-packages/sqlalchemy/engine/base.py", line 473, in _revalidate_connection
    "Can't reconnect until invalid "
sqlalchemy.exc.InvalidRequestError: Can't reconnect until invalid transaction is rolled back

The above exception was the direct cause of the following exception:

Traceback (most recent call last):
  File "/home/fms/project/venv/lib/python3.7/site-packages/flask/app.py", line 2447, in wsgi_app
    response = self.full_dispatch_request()
  File "/home/fms/project/venv/lib/python3.7/site-packages/flask/app.py", line 1952, in full_dispatch_request
    rv = self.handle_user_exception(e)
  File "/home/fms/project/venv/lib/python3.7/site-packages/flask/app.py", line 1821, in handle_user_exception
    reraise(exc_type, exc_value, tb)
  File "/home/fms/project/venv/lib/python3.7/site-packages/flask/_compat.py", line 39, in reraise
    raise value
  File "/home/fms/project/venv/lib/python3.7/site-packages/flask/app.py", line 1950, in full_dispatch_request
    rv = self.dispatch_request()
  File "/home/fms/project/venv/lib/python3.7/site-packages/flask/app.py", line 1936, in dispatch_request
    return self.view_functions[rule.endpoint](**req.view_args)
  File "/home/fms/project/work2database/app.py", line 213, in work2datebase
    wk=week))
  File "/home/fms/project/venv/lib/python3.7/site-packages/sqlalchemy/orm/session.py", line 1292, in execute
    clause, params or {}
  File "/home/fms/project/venv/lib/python3.7/site-packages/sqlalchemy/engine/base.py", line 1014, in execute
    return meth(self, multiparams, params)
  File "/home/fms/project/venv/lib/python3.7/site-packages/sqlalchemy/sql/elements.py", line 298, in _execute_on_connection
    return connection._execute_clauseelement(self, multiparams, params)
  File "/home/fms/project/venv/lib/python3.7/site-packages/sqlalchemy/engine/base.py", line 1133, in _execute_clauseelement
    distilled_params,
  File "/home/fms/project/venv/lib/python3.7/site-packages/sqlalchemy/engine/base.py", line 1208, in _execute_context
    e, util.text_type(statement), parameters, None, None
  File "/home/fms/project/venv/lib/python3.7/site-packages/sqlalchemy/engine/base.py", line 1512, in _handle_dbapi_exception
    sqlalchemy_exception, with_traceback=exc_info[2], from_=e
  File "/home/fms/project/venv/lib/python3.7/site-packages/sqlalchemy/util/compat.py", line 178, in raise_
    raise exception
  File "/home/fms/project/venv/lib/python3.7/site-packages/sqlalchemy/engine/base.py", line 1203, in _execute_context
    conn = self._revalidate_connection()
  File "/home/fms/project/venv/lib/python3.7/site-packages/sqlalchemy/engine/base.py", line 473, in _revalidate_connection
    "Can't reconnect until invalid "
sqlalchemy.exc.StatementError: (sqlalchemy.exc.InvalidRequestError) Can't reconnect until invalid transaction is rolled back
[SQL: SELECT * from `工作周报` where `姓名` = '田中玉' and `周` = 27 and `工作类别` = '安排的工作']
[parameters: [{}]]
[2020-07-03 09:50:36,204] ERROR in app: Exception on /work/ztx [POST]
Traceback (most recent call last):
  File "/home/fms/project/venv/lib/python3.7/site-packages/sqlalchemy/engine/base.py", line 1203, in _execute_context
    conn = self._revalidate_connection()
  File "/home/fms/project/venv/lib/python3.7/site-packages/sqlalchemy/engine/base.py", line 473, in _revalidate_connection
    "Can't reconnect until invalid "
sqlalchemy.exc.InvalidRequestError: Can't reconnect until invalid transaction is rolled back

The above exception was the direct cause of the following exception:

Traceback (most recent call last):
  File "/home/fms/project/venv/lib/python3.7/site-packages/flask/app.py", line 2447, in wsgi_app
    response = self.full_dispatch_request()
  File "/home/fms/project/venv/lib/python3.7/site-packages/flask/app.py", line 1952, in full_dispatch_request
    rv = self.handle_user_exception(e)
  File "/home/fms/project/venv/lib/python3.7/site-packages/flask/app.py", line 1821, in handle_user_exception
    reraise(exc_type, exc_value, tb)
  File "/home/fms/project/venv/lib/python3.7/site-packages/flask/_compat.py", line 39, in reraise
    raise value
  File "/home/fms/project/venv/lib/python3.7/site-packages/flask/app.py", line 1950, in full_dispatch_request
    rv = self.dispatch_request()
  File "/home/fms/project/venv/lib/python3.7/site-packages/flask/app.py", line 1936, in dispatch_request
    return self.view_functions[rule.endpoint](**req.view_args)
  File "/home/fms/project/work2database/app.py", line 213, in work2datebase
    wk=week))
  File "/home/fms/project/venv/lib/python3.7/site-packages/sqlalchemy/orm/session.py", line 1292, in execute
    clause, params or {}
  File "/home/fms/project/venv/lib/python3.7/site-packages/sqlalchemy/engine/base.py", line 1014, in execute
    return meth(self, multiparams, params)
  File "/home/fms/project/venv/lib/python3.7/site-packages/sqlalchemy/sql/elements.py", line 298, in _execute_on_connection
    return connection._execute_clauseelement(self, multiparams, params)
  File "/home/fms/project/venv/lib/python3.7/site-packages/sqlalchemy/engine/base.py", line 1133, in _execute_clauseelement
    distilled_params,
  File "/home/fms/project/venv/lib/python3.7/site-packages/sqlalchemy/engine/base.py", line 1208, in _execute_context
    e, util.text_type(statement), parameters, None, None
  File "/home/fms/project/venv/lib/python3.7/site-packages/sqlalchemy/engine/base.py", line 1512, in _handle_dbapi_exception
    sqlalchemy_exception, with_traceback=exc_info[2], from_=e
  File "/home/fms/project/venv/lib/python3.7/site-packages/sqlalchemy/util/compat.py", line 178, in raise_
    raise exception
  File "/home/fms/project/venv/lib/python3.7/site-packages/sqlalchemy/engine/base.py", line 1203, in _execute_context
    conn = self._revalidate_connection()
  File "/home/fms/project/venv/lib/python3.7/site-packages/sqlalchemy/engine/base.py", line 473, in _revalidate_connection
    "Can't reconnect until invalid "
sqlalchemy.exc.StatementError: (sqlalchemy.exc.InvalidRequestError) Can't reconnect until invalid transaction is rolled back
[SQL: SELECT * from `工作周报` where `姓名` = '查天星' and `周` = 27 and `工作类别` = '安排的工作']
[parameters: [{}]]
[2020-07-03 10:02:34,119] ERROR in app: Exception on /work/tzy [GET]
Traceback (most recent call last):
  File "/home/fms/project/venv/lib/python3.7/site-packages/sqlalchemy/engine/base.py", line 1203, in _execute_context
    conn = self._revalidate_connection()
  File "/home/fms/project/venv/lib/python3.7/site-packages/sqlalchemy/engine/base.py", line 473, in _revalidate_connection
    "Can't reconnect until invalid "
sqlalchemy.exc.InvalidRequestError: Can't reconnect until invalid transaction is rolled back

The above exception was the direct cause of the following exception:

Traceback (most recent call last):
  File "/home/fms/project/venv/lib/python3.7/site-packages/flask/app.py", line 2447, in wsgi_app
    response = self.full_dispatch_request()
  File "/home/fms/project/venv/lib/python3.7/site-packages/flask/app.py", line 1952, in full_dispatch_request
    rv = self.handle_user_exception(e)
  File "/home/fms/project/venv/lib/python3.7/site-packages/flask/app.py", line 1821, in handle_user_exception
    reraise(exc_type, exc_value, tb)
  File "/home/fms/project/venv/lib/python3.7/site-packages/flask/_compat.py", line 39, in reraise
    raise value
  File "/home/fms/project/venv/lib/python3.7/site-packages/flask/app.py", line 1950, in full_dispatch_request
    rv = self.dispatch_request()
  File "/home/fms/project/venv/lib/python3.7/site-packages/flask/app.py", line 1936, in dispatch_request
    return self.view_functions[rule.endpoint](**req.view_args)
  File "/home/fms/project/work2database/app.py", line 213, in work2datebase
    wk=week))
  File "/home/fms/project/venv/lib/python3.7/site-packages/sqlalchemy/orm/session.py", line 1292, in execute
    clause, params or {}
  File "/home/fms/project/venv/lib/python3.7/site-packages/sqlalchemy/engine/base.py", line 1014, in execute
    return meth(self, multiparams, params)
  File "/home/fms/project/venv/lib/python3.7/site-packages/sqlalchemy/sql/elements.py", line 298, in _execute_on_connection
    return connection._execute_clauseelement(self, multiparams, params)
  File "/home/fms/project/venv/lib/python3.7/site-packages/sqlalchemy/engine/base.py", line 1133, in _execute_clauseelement
    distilled_params,
  File "/home/fms/project/venv/lib/python3.7/site-packages/sqlalchemy/engine/base.py", line 1208, in _execute_context
    e, util.text_type(statement), parameters, None, None
  File "/home/fms/project/venv/lib/python3.7/site-packages/sqlalchemy/engine/base.py", line 1512, in _handle_dbapi_exception
    sqlalchemy_exception, with_traceback=exc_info[2], from_=e
  File "/home/fms/project/venv/lib/python3.7/site-packages/sqlalchemy/util/compat.py", line 178, in raise_
    raise exception
  File "/home/fms/project/venv/lib/python3.7/site-packages/sqlalchemy/engine/base.py", line 1203, in _execute_context
    conn = self._revalidate_connection()
  File "/home/fms/project/venv/lib/python3.7/site-packages/sqlalchemy/engine/base.py", line 473, in _revalidate_connection
    "Can't reconnect until invalid "
sqlalchemy.exc.StatementError: (sqlalchemy.exc.InvalidRequestError) Can't reconnect until invalid transaction is rolled back
[SQL: SELECT * from `工作周报` where `姓名` = '田中玉' and `周` = 27 and `工作类别` = '安排的工作']
[parameters: [{}]]
[2020-07-03 10:03:08,936] ERROR in app: Exception on /work/tzy [GET]
Traceback (most recent call last):
  File "/home/fms/project/venv/lib/python3.7/site-packages/sqlalchemy/engine/base.py", line 1203, in _execute_context
    conn = self._revalidate_connection()
  File "/home/fms/project/venv/lib/python3.7/site-packages/sqlalchemy/engine/base.py", line 473, in _revalidate_connection
    "Can't reconnect until invalid "
sqlalchemy.exc.InvalidRequestError: Can't reconnect until invalid transaction is rolled back

The above exception was the direct cause of the following exception:

Traceback (most recent call last):
  File "/home/fms/project/venv/lib/python3.7/site-packages/flask/app.py", line 2447, in wsgi_app
    response = self.full_dispatch_request()
  File "/home/fms/project/venv/lib/python3.7/site-packages/flask/app.py", line 1952, in full_dispatch_request
    rv = self.handle_user_exception(e)
  File "/home/fms/project/venv/lib/python3.7/site-packages/flask/app.py", line 1821, in handle_user_exception
    reraise(exc_type, exc_value, tb)
  File "/home/fms/project/venv/lib/python3.7/site-packages/flask/_compat.py", line 39, in reraise
    raise value
  File "/home/fms/project/venv/lib/python3.7/site-packages/flask/app.py", line 1950, in full_dispatch_request
    rv = self.dispatch_request()
  File "/home/fms/project/venv/lib/python3.7/site-packages/flask/app.py", line 1936, in dispatch_request
    return self.view_functions[rule.endpoint](**req.view_args)
  File "/home/fms/project/work2database/app.py", line 213, in work2datebase
    wk=week))
  File "/home/fms/project/venv/lib/python3.7/site-packages/sqlalchemy/orm/session.py", line 1292, in execute
    clause, params or {}
  File "/home/fms/project/venv/lib/python3.7/site-packages/sqlalchemy/engine/base.py", line 1014, in execute
    return meth(self, multiparams, params)
  File "/home/fms/project/venv/lib/python3.7/site-packages/sqlalchemy/sql/elements.py", line 298, in _execute_on_connection
    return connection._execute_clauseelement(self, multiparams, params)
  File "/home/fms/project/venv/lib/python3.7/site-packages/sqlalchemy/engine/base.py", line 1133, in _execute_clauseelement
    distilled_params,
  File "/home/fms/project/venv/lib/python3.7/site-packages/sqlalchemy/engine/base.py", line 1208, in _execute_context
    e, util.text_type(statement), parameters, None, None
  File "/home/fms/project/venv/lib/python3.7/site-packages/sqlalchemy/engine/base.py", line 1512, in _handle_dbapi_exception
    sqlalchemy_exception, with_traceback=exc_info[2], from_=e
  File "/home/fms/project/venv/lib/python3.7/site-packages/sqlalchemy/util/compat.py", line 178, in raise_
    raise exception
  File "/home/fms/project/venv/lib/python3.7/site-packages/sqlalchemy/engine/base.py", line 1203, in _execute_context
    conn = self._revalidate_connection()
  File "/home/fms/project/venv/lib/python3.7/site-packages/sqlalchemy/engine/base.py", line 473, in _revalidate_connection
    "Can't reconnect until invalid "
sqlalchemy.exc.StatementError: (sqlalchemy.exc.InvalidRequestError) Can't reconnect until invalid transaction is rolled back
[SQL: SELECT * from `工作周报` where `姓名` = '田中玉' and `周` = 27 and `工作类别` = '安排的工作']
[parameters: [{}]]
[2020-07-03 10:03:12,274] ERROR in app: Exception on /work/fms [GET]
Traceback (most recent call last):
  File "/home/fms/project/venv/lib/python3.7/site-packages/sqlalchemy/engine/base.py", line 1203, in _execute_context
    conn = self._revalidate_connection()
  File "/home/fms/project/venv/lib/python3.7/site-packages/sqlalchemy/engine/base.py", line 473, in _revalidate_connection
    "Can't reconnect until invalid "
sqlalchemy.exc.InvalidRequestError: Can't reconnect until invalid transaction is rolled back

The above exception was the direct cause of the following exception:

Traceback (most recent call last):
  File "/home/fms/project/venv/lib/python3.7/site-packages/flask/app.py", line 2447, in wsgi_app
    response = self.full_dispatch_request()
  File "/home/fms/project/venv/lib/python3.7/site-packages/flask/app.py", line 1952, in full_dispatch_request
    rv = self.handle_user_exception(e)
  File "/home/fms/project/venv/lib/python3.7/site-packages/flask/app.py", line 1821, in handle_user_exception
    reraise(exc_type, exc_value, tb)
  File "/home/fms/project/venv/lib/python3.7/site-packages/flask/_compat.py", line 39, in reraise
    raise value
  File "/home/fms/project/venv/lib/python3.7/site-packages/flask/app.py", line 1950, in full_dispatch_request
    rv = self.dispatch_request()
  File "/home/fms/project/venv/lib/python3.7/site-packages/flask/app.py", line 1936, in dispatch_request
    return self.view_functions[rule.endpoint](**req.view_args)
  File "/home/fms/project/work2database/app.py", line 213, in work2datebase
    wk=week))
  File "/home/fms/project/venv/lib/python3.7/site-packages/sqlalchemy/orm/session.py", line 1292, in execute
    clause, params or {}
  File "/home/fms/project/venv/lib/python3.7/site-packages/sqlalchemy/engine/base.py", line 1014, in execute
    return meth(self, multiparams, params)
  File "/home/fms/project/venv/lib/python3.7/site-packages/sqlalchemy/sql/elements.py", line 298, in _execute_on_connection
    return connection._execute_clauseelement(self, multiparams, params)
  File "/home/fms/project/venv/lib/python3.7/site-packages/sqlalchemy/engine/base.py", line 1133, in _execute_clauseelement
    distilled_params,
  File "/home/fms/project/venv/lib/python3.7/site-packages/sqlalchemy/engine/base.py", line 1208, in _execute_context
    e, util.text_type(statement), parameters, None, None
  File "/home/fms/project/venv/lib/python3.7/site-packages/sqlalchemy/engine/base.py", line 1512, in _handle_dbapi_exception
    sqlalchemy_exception, with_traceback=exc_info[2], from_=e
  File "/home/fms/project/venv/lib/python3.7/site-packages/sqlalchemy/util/compat.py", line 178, in raise_
    raise exception
  File "/home/fms/project/venv/lib/python3.7/site-packages/sqlalchemy/engine/base.py", line 1203, in _execute_context
    conn = self._revalidate_connection()
  File "/home/fms/project/venv/lib/python3.7/site-packages/sqlalchemy/engine/base.py", line 473, in _revalidate_connection
    "Can't reconnect until invalid "
sqlalchemy.exc.StatementError: (sqlalchemy.exc.InvalidRequestError) Can't reconnect until invalid transaction is rolled back
[SQL: SELECT * from `工作周报` where `姓名` = '冯明山' and `周` = 27 and `工作类别` = '安排的工作']
[parameters: [{}]]
[2020-07-03 10:03:26 +0800] [2238] [INFO] Handling signal: term
[2020-07-03 10:03:26 +0800] [2249] [INFO] Worker exiting (pid: 2249)
[2020-07-03 10:03:26 +0800] [2246] [INFO] Worker exiting (pid: 2246)
[2020-07-03 10:03:26 +0800] [2242] [INFO] Worker exiting (pid: 2242)
[2020-07-03 10:03:26 +0800] [2245] [INFO] Worker exiting (pid: 2245)
[2020-07-03 10:03:26 +0800] [2238] [INFO] Shutting down: Master
[2020-07-03 10:03:28 +0800] [2288] [INFO] Starting gunicorn 20.0.4
[2020-07-03 10:03:28 +0800] [2288] [INFO] Listening at: http://0.0.0.0:8002 (2288)
[2020-07-03 10:03:28 +0800] [2288] [INFO] Using worker: sync
[2020-07-03 10:03:28 +0800] [2291] [INFO] Booting worker with pid: 2291
[2020-07-03 10:03:28 +0800] [2292] [INFO] Booting worker with pid: 2292
[2020-07-03 10:03:28 +0800] [2293] [INFO] Booting worker with pid: 2293
[2020-07-03 10:03:28 +0800] [2294] [INFO] Booting worker with pid: 2294
[2020-07-03 10:04:28 +0800] [2288] [INFO] Handling signal: term
/home/fms/project/venv/lib/python3.7/site-packages/pymysql/cursors.py:170: Warning: (1366, "Incorrect string value: '\\xD6\\xD0\\xB9\\xFA\\xB1\\xEA...' for column 'VARIABLE_VALUE' at row 480")
  result = self._query(query)
[2020-07-03 10:04:28 +0800] [2294] [INFO] Worker exiting (pid: 2294)
[2020-07-03 10:04:28 +0800] [2293] [INFO] Worker exiting (pid: 2293)
[2020-07-03 10:04:28 +0800] [2292] [INFO] Worker exiting (pid: 2292)
[2020-07-03 10:04:28 +0800] [2291] [INFO] Worker exiting (pid: 2291)
[2020-07-03 10:04:28 +0800] [2288] [INFO] Shutting down: Master
[2020-07-03 10:04:30 +0800] [2298] [INFO] Starting gunicorn 20.0.4
[2020-07-03 10:04:30 +0800] [2298] [INFO] Listening at: http://0.0.0.0:8002 (2298)
[2020-07-03 10:04:30 +0800] [2298] [INFO] Using worker: sync
[2020-07-03 10:04:30 +0800] [2301] [INFO] Booting worker with pid: 2301
[2020-07-03 10:04:30 +0800] [2302] [INFO] Booting worker with pid: 2302
[2020-07-03 10:04:30 +0800] [2303] [INFO] Booting worker with pid: 2303
[2020-07-03 10:04:30 +0800] [2304] [INFO] Booting worker with pid: 2304
[2020-07-03 10:08:22 +0800] [2298] [INFO] Handling signal: term
/home/fms/project/venv/lib/python3.7/site-packages/pymysql/cursors.py:170: Warning: (1366, "Incorrect string value: '\\xD6\\xD0\\xB9\\xFA\\xB1\\xEA...' for column 'VARIABLE_VALUE' at row 480")
  result = self._query(query)
[2020-07-03 10:08:22 +0800] [2304] [INFO] Worker exiting (pid: 2304)
/home/fms/project/venv/lib/python3.7/site-packages/pymysql/cursors.py:170: Warning: (1366, "Incorrect string value: '\\xD6\\xD0\\xB9\\xFA\\xB1\\xEA...' for column 'VARIABLE_VALUE' at row 480")
  result = self._query(query)
[2020-07-03 10:08:22 +0800] [2303] [INFO] Worker exiting (pid: 2303)
/home/fms/project/venv/lib/python3.7/site-packages/pymysql/cursors.py:170: Warning: (1366, "Incorrect string value: '\\xD6\\xD0\\xB9\\xFA\\xB1\\xEA...' for column 'VARIABLE_VALUE' at row 480")
  result = self._query(query)
[2020-07-03 10:08:22 +0800] [2302] [INFO] Worker exiting (pid: 2302)
/home/fms/project/venv/lib/python3.7/site-packages/pymysql/cursors.py:170: Warning: (1366, "Incorrect string value: '\\xD6\\xD0\\xB9\\xFA\\xB1\\xEA...' for column 'VARIABLE_VALUE' at row 480")
  result = self._query(query)
[2020-07-03 10:08:22 +0800] [2301] [INFO] Worker exiting (pid: 2301)
[2020-07-03 10:08:22 +0800] [2298] [INFO] Shutting down: Master
[2020-07-03 10:08:23 +0800] [2305] [INFO] Starting gunicorn 20.0.4
[2020-07-03 10:08:23 +0800] [2305] [INFO] Listening at: http://0.0.0.0:8002 (2305)
[2020-07-03 10:08:23 +0800] [2305] [INFO] Using worker: sync
[2020-07-03 10:08:23 +0800] [2308] [INFO] Booting worker with pid: 2308
[2020-07-03 10:08:23 +0800] [2309] [INFO] Booting worker with pid: 2309
[2020-07-03 10:08:23 +0800] [2310] [INFO] Booting worker with pid: 2310
[2020-07-03 10:08:23 +0800] [2311] [INFO] Booting worker with pid: 2311
/home/fms/project/venv/lib/python3.7/site-packages/pymysql/cursors.py:170: Warning: (1366, "Incorrect string value: '\\xD6\\xD0\\xB9\\xFA\\xB1\\xEA...' for column 'VARIABLE_VALUE' at row 480")
  result = self._query(query)
[2020-07-03 10:51:08,977] ERROR in app: Exception on /put [POST]
Traceback (most recent call last):
  File "/home/fms/project/venv/lib/python3.7/site-packages/sqlalchemy/engine/base.py", line 1278, in _execute_context
    cursor, statement, parameters, context
  File "/home/fms/project/venv/lib/python3.7/site-packages/sqlalchemy/engine/default.py", line 593, in do_execute
    cursor.execute(statement, parameters)
  File "/home/fms/project/venv/lib/python3.7/site-packages/pymysql/cursors.py", line 170, in execute
    result = self._query(query)
  File "/home/fms/project/venv/lib/python3.7/site-packages/pymysql/cursors.py", line 328, in _query
    conn.query(q)
  File "/home/fms/project/venv/lib/python3.7/site-packages/pymysql/connections.py", line 517, in query
    self._affected_rows = self._read_query_result(unbuffered=unbuffered)
  File "/home/fms/project/venv/lib/python3.7/site-packages/pymysql/connections.py", line 732, in _read_query_result
    result.read()
  File "/home/fms/project/venv/lib/python3.7/site-packages/pymysql/connections.py", line 1075, in read
    first_packet = self.connection._read_packet()
  File "/home/fms/project/venv/lib/python3.7/site-packages/pymysql/connections.py", line 657, in _read_packet
    packet_header = self._read_bytes(4)
  File "/home/fms/project/venv/lib/python3.7/site-packages/pymysql/connections.py", line 707, in _read_bytes
    CR.CR_SERVER_LOST, "Lost connection to MySQL server during query")
pymysql.err.OperationalError: (2013, 'Lost connection to MySQL server during query')

The above exception was the direct cause of the following exception:

Traceback (most recent call last):
  File "/home/fms/project/venv/lib/python3.7/site-packages/flask/app.py", line 2447, in wsgi_app
    response = self.full_dispatch_request()
  File "/home/fms/project/venv/lib/python3.7/site-packages/flask/app.py", line 1952, in full_dispatch_request
    rv = self.handle_user_exception(e)
  File "/home/fms/project/venv/lib/python3.7/site-packages/flask/app.py", line 1821, in handle_user_exception
    reraise(exc_type, exc_value, tb)
  File "/home/fms/project/venv/lib/python3.7/site-packages/flask/_compat.py", line 39, in reraise
    raise value
  File "/home/fms/project/venv/lib/python3.7/site-packages/flask/app.py", line 1950, in full_dispatch_request
    rv = self.dispatch_request()
  File "/home/fms/project/venv/lib/python3.7/site-packages/flask/app.py", line 1936, in dispatch_request
    return self.view_functions[rule.endpoint](**req.view_args)
  File "/home/fms/project/work2database/app.py", line 102, in put2datebase
    item = session_tousu.execute('select * from tousu order by 工单流水号 asc')
  File "/home/fms/project/venv/lib/python3.7/site-packages/sqlalchemy/orm/session.py", line 1292, in execute
    clause, params or {}
  File "/home/fms/project/venv/lib/python3.7/site-packages/sqlalchemy/engine/base.py", line 1014, in execute
    return meth(self, multiparams, params)
  File "/home/fms/project/venv/lib/python3.7/site-packages/sqlalchemy/sql/elements.py", line 298, in _execute_on_connection
    return connection._execute_clauseelement(self, multiparams, params)
  File "/home/fms/project/venv/lib/python3.7/site-packages/sqlalchemy/engine/base.py", line 1133, in _execute_clauseelement
    distilled_params,
  File "/home/fms/project/venv/lib/python3.7/site-packages/sqlalchemy/engine/base.py", line 1318, in _execute_context
    e, statement, parameters, cursor, context
  File "/home/fms/project/venv/lib/python3.7/site-packages/sqlalchemy/engine/base.py", line 1512, in _handle_dbapi_exception
    sqlalchemy_exception, with_traceback=exc_info[2], from_=e
  File "/home/fms/project/venv/lib/python3.7/site-packages/sqlalchemy/util/compat.py", line 178, in raise_
    raise exception
  File "/home/fms/project/venv/lib/python3.7/site-packages/sqlalchemy/engine/base.py", line 1278, in _execute_context
    cursor, statement, parameters, context
  File "/home/fms/project/venv/lib/python3.7/site-packages/sqlalchemy/engine/default.py", line 593, in do_execute
    cursor.execute(statement, parameters)
  File "/home/fms/project/venv/lib/python3.7/site-packages/pymysql/cursors.py", line 170, in execute
    result = self._query(query)
  File "/home/fms/project/venv/lib/python3.7/site-packages/pymysql/cursors.py", line 328, in _query
    conn.query(q)
  File "/home/fms/project/venv/lib/python3.7/site-packages/pymysql/connections.py", line 517, in query
    self._affected_rows = self._read_query_result(unbuffered=unbuffered)
  File "/home/fms/project/venv/lib/python3.7/site-packages/pymysql/connections.py", line 732, in _read_query_result
    result.read()
  File "/home/fms/project/venv/lib/python3.7/site-packages/pymysql/connections.py", line 1075, in read
    first_packet = self.connection._read_packet()
  File "/home/fms/project/venv/lib/python3.7/site-packages/pymysql/connections.py", line 657, in _read_packet
    packet_header = self._read_bytes(4)
  File "/home/fms/project/venv/lib/python3.7/site-packages/pymysql/connections.py", line 707, in _read_bytes
    CR.CR_SERVER_LOST, "Lost connection to MySQL server during query")
sqlalchemy.exc.OperationalError: (pymysql.err.OperationalError) (2013, 'Lost connection to MySQL server during query')
[SQL: select * from tousu order by 工单流水号 asc]
(Background on this error at: http://sqlalche.me/e/13/e3q8)
[2020-07-03 10:51:20 +0800] [2305] [INFO] Handling signal: term
/home/fms/project/venv/lib/python3.7/site-packages/pymysql/cursors.py:170: Warning: (1366, "Incorrect string value: '\\xD6\\xD0\\xB9\\xFA\\xB1\\xEA...' for column 'VARIABLE_VALUE' at row 480")
  result = self._query(query)
[2020-07-03 10:51:20 +0800] [2308] [INFO] Worker exiting (pid: 2308)
/home/fms/project/venv/lib/python3.7/site-packages/pymysql/cursors.py:170: Warning: (1366, "Incorrect string value: '\\xD6\\xD0\\xB9\\xFA\\xB1\\xEA...' for column 'VARIABLE_VALUE' at row 480")
  result = self._query(query)
[2020-07-03 10:51:20 +0800] [2309] [INFO] Worker exiting (pid: 2309)
[2020-07-03 10:51:20 +0800] [2310] [INFO] Worker exiting (pid: 2310)
/home/fms/project/venv/lib/python3.7/site-packages/pymysql/cursors.py:170: Warning: (1366, "Incorrect string value: '\\xD6\\xD0\\xB9\\xFA\\xB1\\xEA...' for column 'VARIABLE_VALUE' at row 480")
  result = self._query(query)
[2020-07-03 10:51:20 +0800] [2311] [INFO] Worker exiting (pid: 2311)
[2020-07-03 10:51:21 +0800] [2305] [INFO] Shutting down: Master
[2020-07-03 10:51:23 +0800] [2504] [INFO] Starting gunicorn 20.0.4
[2020-07-03 10:51:23 +0800] [2504] [INFO] Listening at: http://0.0.0.0:8002 (2504)
[2020-07-03 10:51:23 +0800] [2504] [INFO] Using worker: sync
[2020-07-03 10:51:23 +0800] [2512] [INFO] Booting worker with pid: 2512
[2020-07-03 10:51:23 +0800] [2514] [INFO] Booting worker with pid: 2514
[2020-07-03 10:51:23 +0800] [2515] [INFO] Booting worker with pid: 2515
[2020-07-03 10:51:23 +0800] [2516] [INFO] Booting worker with pid: 2516
/home/fms/project/venv/lib/python3.7/site-packages/pymysql/cursors.py:170: Warning: (1366, "Incorrect string value: '\\xD6\\xD0\\xB9\\xFA\\xB1\\xEA...' for column 'VARIABLE_VALUE' at row 480")
  result = self._query(query)
[2020-07-03 11:49:42,839] ERROR in app: Exception on /put [POST]
Traceback (most recent call last):
  File "/home/fms/project/venv/lib/python3.7/site-packages/sqlalchemy/engine/base.py", line 1278, in _execute_context
    cursor, statement, parameters, context
  File "/home/fms/project/venv/lib/python3.7/site-packages/sqlalchemy/engine/default.py", line 593, in do_execute
    cursor.execute(statement, parameters)
  File "/home/fms/project/venv/lib/python3.7/site-packages/pymysql/cursors.py", line 170, in execute
    result = self._query(query)
  File "/home/fms/project/venv/lib/python3.7/site-packages/pymysql/cursors.py", line 328, in _query
    conn.query(q)
  File "/home/fms/project/venv/lib/python3.7/site-packages/pymysql/connections.py", line 517, in query
    self._affected_rows = self._read_query_result(unbuffered=unbuffered)
  File "/home/fms/project/venv/lib/python3.7/site-packages/pymysql/connections.py", line 732, in _read_query_result
    result.read()
  File "/home/fms/project/venv/lib/python3.7/site-packages/pymysql/connections.py", line 1075, in read
    first_packet = self.connection._read_packet()
  File "/home/fms/project/venv/lib/python3.7/site-packages/pymysql/connections.py", line 684, in _read_packet
    packet.check_error()
  File "/home/fms/project/venv/lib/python3.7/site-packages/pymysql/protocol.py", line 220, in check_error
    err.raise_mysql_exception(self._data)
  File "/home/fms/project/venv/lib/python3.7/site-packages/pymysql/err.py", line 109, in raise_mysql_exception
    raise errorclass(errno, errval)
pymysql.err.DataError: (1406, "Data too long for column '经度' at row 1")

The above exception was the direct cause of the following exception:

Traceback (most recent call last):
  File "/home/fms/project/venv/lib/python3.7/site-packages/flask/app.py", line 2447, in wsgi_app
    response = self.full_dispatch_request()
  File "/home/fms/project/venv/lib/python3.7/site-packages/flask/app.py", line 1952, in full_dispatch_request
    rv = self.handle_user_exception(e)
  File "/home/fms/project/venv/lib/python3.7/site-packages/flask/app.py", line 1821, in handle_user_exception
    reraise(exc_type, exc_value, tb)
  File "/home/fms/project/venv/lib/python3.7/site-packages/flask/_compat.py", line 39, in reraise
    raise value
  File "/home/fms/project/venv/lib/python3.7/site-packages/flask/app.py", line 1950, in full_dispatch_request
    rv = self.dispatch_request()
  File "/home/fms/project/venv/lib/python3.7/site-packages/flask/app.py", line 1936, in dispatch_request
    return self.view_functions[rule.endpoint](**req.view_args)
  File "/home/fms/project/work2database/app.py", line 108, in put2datebase
    put2base(complaint_info, session_tousu)
  File "/home/fms/project/work2database/func.py", line 65, in put2base
    session3.commit()
  File "/home/fms/project/venv/lib/python3.7/site-packages/sqlalchemy/orm/session.py", line 1042, in commit
    self.transaction.commit()
  File "/home/fms/project/venv/lib/python3.7/site-packages/sqlalchemy/orm/session.py", line 504, in commit
    self._prepare_impl()
  File "/home/fms/project/venv/lib/python3.7/site-packages/sqlalchemy/orm/session.py", line 483, in _prepare_impl
    self.session.flush()
  File "/home/fms/project/venv/lib/python3.7/site-packages/sqlalchemy/orm/session.py", line 2523, in flush
    self._flush(objects)
  File "/home/fms/project/venv/lib/python3.7/site-packages/sqlalchemy/orm/session.py", line 2664, in _flush
    transaction.rollback(_capture_exception=True)
  File "/home/fms/project/venv/lib/python3.7/site-packages/sqlalchemy/util/langhelpers.py", line 69, in __exit__
    exc_value, with_traceback=exc_tb,
  File "/home/fms/project/venv/lib/python3.7/site-packages/sqlalchemy/util/compat.py", line 178, in raise_
    raise exception
  File "/home/fms/project/venv/lib/python3.7/site-packages/sqlalchemy/orm/session.py", line 2624, in _flush
    flush_context.execute()
  File "/home/fms/project/venv/lib/python3.7/site-packages/sqlalchemy/orm/unitofwork.py", line 422, in execute
    rec.execute(self)
  File "/home/fms/project/venv/lib/python3.7/site-packages/sqlalchemy/orm/unitofwork.py", line 589, in execute
    uow,
  File "/home/fms/project/venv/lib/python3.7/site-packages/sqlalchemy/orm/persistence.py", line 245, in save_obj
    insert,
  File "/home/fms/project/venv/lib/python3.7/site-packages/sqlalchemy/orm/persistence.py", line 1083, in _emit_insert_statements
    c = cached_connections[connection].execute(statement, multiparams)
  File "/home/fms/project/venv/lib/python3.7/site-packages/sqlalchemy/engine/base.py", line 1014, in execute
    return meth(self, multiparams, params)
  File "/home/fms/project/venv/lib/python3.7/site-packages/sqlalchemy/sql/elements.py", line 298, in _execute_on_connection
    return connection._execute_clauseelement(self, multiparams, params)
  File "/home/fms/project/venv/lib/python3.7/site-packages/sqlalchemy/engine/base.py", line 1133, in _execute_clauseelement
    distilled_params,
  File "/home/fms/project/venv/lib/python3.7/site-packages/sqlalchemy/engine/base.py", line 1318, in _execute_context
    e, statement, parameters, cursor, context
  File "/home/fms/project/venv/lib/python3.7/site-packages/sqlalchemy/engine/base.py", line 1512, in _handle_dbapi_exception
    sqlalchemy_exception, with_traceback=exc_info[2], from_=e
  File "/home/fms/project/venv/lib/python3.7/site-packages/sqlalchemy/util/compat.py", line 178, in raise_
    raise exception
  File "/home/fms/project/venv/lib/python3.7/site-packages/sqlalchemy/engine/base.py", line 1278, in _execute_context
    cursor, statement, parameters, context
  File "/home/fms/project/venv/lib/python3.7/site-packages/sqlalchemy/engine/default.py", line 593, in do_execute
    cursor.execute(statement, parameters)
  File "/home/fms/project/venv/lib/python3.7/site-packages/pymysql/cursors.py", line 170, in execute
    result = self._query(query)
  File "/home/fms/project/venv/lib/python3.7/site-packages/pymysql/cursors.py", line 328, in _query
    conn.query(q)
  File "/home/fms/project/venv/lib/python3.7/site-packages/pymysql/connections.py", line 517, in query
    self._affected_rows = self._read_query_result(unbuffered=unbuffered)
  File "/home/fms/project/venv/lib/python3.7/site-packages/pymysql/connections.py", line 732, in _read_query_result
    result.read()
  File "/home/fms/project/venv/lib/python3.7/site-packages/pymysql/connections.py", line 1075, in read
    first_packet = self.connection._read_packet()
  File "/home/fms/project/venv/lib/python3.7/site-packages/pymysql/connections.py", line 684, in _read_packet
    packet.check_error()
  File "/home/fms/project/venv/lib/python3.7/site-packages/pymysql/protocol.py", line 220, in check_error
    err.raise_mysql_exception(self._data)
  File "/home/fms/project/venv/lib/python3.7/site-packages/pymysql/err.py", line 109, in raise_mysql_exception
    raise errorclass(errno, errval)
sqlalchemy.exc.DataError: (pymysql.err.DataError) (1406, "Data too long for column '经度' at row 1")
[SQL: INSERT INTO tousu (`工单流水号`, `投诉内容`, `处理结果`, `我方办结原因`, `区县`, `乡镇`, `关联自然村_小区名`, `经度`, `纬度`, `关联基站代码`, `关联基站名称`, `投诉大类`, `投诉原因`, `网络类型`, `区域`, `区域细类`, `解决措施`, `解决措施_详`) VALUES (%(工单流水号)s, %(投诉内容)s, %(处理结果)s, %(我方办结原因)s, %(区县)s, %(乡镇)s, %(关联自然村_小区名)s, %(经度)s, %(纬度)s, %(关联基站代码)s, %(关联基站名称)s, %(投诉大类)s, %(投诉原因)s, %(网络类型)s, %(区域)s, %(区域细类)s, %(解决措施)s, %(解决措施_详)s)]
[parameters: {'工单流水号': 'TZ0000202007027856056', '投诉内容': '故障地址：云南曲靖宣威西临镇附近（用户不愿意提供详细的地址）\r\n用户反映：本机无法正常上网，有3G信号，不愿意预处理和提供手机型号，无法启动移动故障专区，要求查询原因并处理', '处理结果': '投诉产生原因：深度覆盖\r\n经过核实，该地点属马家山_场景，该地点属于密集住宅小区，我方已经在小区周围建设了2个基站，周围房屋比较密集，有阻挡，导致我方基站深度覆盖不稳定。必须通过后期补点建站解决，目前省公司暂无建设投资计划，分公司只能执行省公司的建设计划，所以我方也无法给出具体解决时间，建议在室内使用有线宽带，我方已和用户解释过，用户同意，无须回访。', '我方办结原因': '弱覆盖', '区县': '宣威', '乡镇': '西宁', '关联自然村_小区名': '马家山', '经度': ' 104.089129', '纬度': '26.225236', '关联基站代码': '', '关联基站名称': '', '投诉大类': None, '投诉原因': None, '网络类型': None, '区域': '城区', '区域细类': '住宅小区', '解决措施': '使用WIFI替代', '解决措施_详': None}]
(Background on this error at: http://sqlalche.me/e/13/9h9h)
[2020-07-03 14:45:10 +0800] [2504] [INFO] Handling signal: term
/home/fms/project/venv/lib/python3.7/site-packages/pymysql/cursors.py:170: Warning: (1366, "Incorrect string value: '\\xD6\\xD0\\xB9\\xFA\\xB1\\xEA...' for column 'VARIABLE_VALUE' at row 480")
  result = self._query(query)
[2020-07-03 14:45:13 +0800] [2512] [INFO] Worker exiting (pid: 2512)
/home/fms/project/venv/lib/python3.7/site-packages/pymysql/cursors.py:170: Warning: (1366, "Incorrect string value: '\\xD6\\xD0\\xB9\\xFA\\xB1\\xEA...' for column 'VARIABLE_VALUE' at row 480")
  result = self._query(query)
[2020-07-03 14:45:14 +0800] [2515] [INFO] Worker exiting (pid: 2515)
[2020-07-03 14:45:14 +0800] [2516] [INFO] Worker exiting (pid: 2516)
/home/fms/project/venv/lib/python3.7/site-packages/pymysql/cursors.py:170: Warning: (1366, "Incorrect string value: '\\xD6\\xD0\\xB9\\xFA\\xB1\\xEA...' for column 'VARIABLE_VALUE' at row 480")
  result = self._query(query)
[2020-07-03 14:45:13 +0800] [2514] [INFO] Worker exiting (pid: 2514)
[2020-07-03 14:49:21 +0800] [2613] [INFO] Starting gunicorn 20.0.4
[2020-07-03 14:49:21 +0800] [2613] [INFO] Listening at: http://0.0.0.0:8002 (2613)
[2020-07-03 14:49:21 +0800] [2613] [INFO] Using worker: sync
[2020-07-03 14:49:21 +0800] [2616] [INFO] Booting worker with pid: 2616
[2020-07-03 14:49:21 +0800] [2617] [INFO] Booting worker with pid: 2617
[2020-07-03 14:49:22 +0800] [2618] [INFO] Booting worker with pid: 2618
[2020-07-03 14:49:22 +0800] [2619] [INFO] Booting worker with pid: 2619
[2020-07-03 15:22:09 +0800] [2613] [INFO] Handling signal: term
/home/fms/project/venv/lib/python3.7/site-packages/pymysql/cursors.py:170: Warning: (1366, "Incorrect string value: '\\xD6\\xD0\\xB9\\xFA\\xB1\\xEA...' for column 'VARIABLE_VALUE' at row 480")
  result = self._query(query)
[2020-07-03 15:22:09 +0800] [2617] [INFO] Worker exiting (pid: 2617)
/home/fms/project/venv/lib/python3.7/site-packages/pymysql/cursors.py:170: Warning: (1366, "Incorrect string value: '\\xD6\\xD0\\xB9\\xFA\\xB1\\xEA...' for column 'VARIABLE_VALUE' at row 480")
  result = self._query(query)
[2020-07-03 15:22:09 +0800] [2616] [INFO] Worker exiting (pid: 2616)
/home/fms/project/venv/lib/python3.7/site-packages/pymysql/cursors.py:170: Warning: (1366, "Incorrect string value: '\\xD6\\xD0\\xB9\\xFA\\xB1\\xEA...' for column 'VARIABLE_VALUE' at row 480")
  result = self._query(query)
[2020-07-03 15:22:09 +0800] [2619] [INFO] Worker exiting (pid: 2619)
/home/fms/project/venv/lib/python3.7/site-packages/pymysql/cursors.py:170: Warning: (1366, "Incorrect string value: '\\xD6\\xD0\\xB9\\xFA\\xB1\\xEA...' for column 'VARIABLE_VALUE' at row 480")
  result = self._query(query)
[2020-07-03 15:22:09 +0800] [2618] [INFO] Worker exiting (pid: 2618)
[2020-07-03 15:22:09 +0800] [2613] [INFO] Shutting down: Master
[2020-07-03 15:22:12 +0800] [2654] [INFO] Starting gunicorn 20.0.4
[2020-07-03 15:22:12 +0800] [2654] [INFO] Listening at: http://0.0.0.0:8002 (2654)
[2020-07-03 15:22:12 +0800] [2654] [INFO] Using worker: sync
[2020-07-03 15:22:12 +0800] [2660] [INFO] Booting worker with pid: 2660
[2020-07-03 15:22:12 +0800] [2661] [INFO] Booting worker with pid: 2661
[2020-07-03 15:22:12 +0800] [2662] [INFO] Booting worker with pid: 2662
[2020-07-03 15:22:12 +0800] [2665] [INFO] Booting worker with pid: 2665
[2020-07-03 15:22:13 +0800] [2654] [INFO] Handling signal: term
[2020-07-03 15:22:13 +0800] [2660] [INFO] Worker exiting (pid: 2660)
[2020-07-03 15:22:13 +0800] [2662] [INFO] Worker exiting (pid: 2662)
[2020-07-03 15:22:13 +0800] [2661] [INFO] Worker exiting (pid: 2661)
[2020-07-03 15:22:13 +0800] [2665] [INFO] Worker exiting (pid: 2665)
[2020-07-03 15:22:14 +0800] [2654] [INFO] Shutting down: Master
[2020-07-03 15:22:15 +0800] [2668] [INFO] Starting gunicorn 20.0.4
[2020-07-03 15:22:15 +0800] [2668] [INFO] Listening at: http://0.0.0.0:8002 (2668)
[2020-07-03 15:22:15 +0800] [2668] [INFO] Using worker: sync
[2020-07-03 15:22:15 +0800] [2674] [INFO] Booting worker with pid: 2674
[2020-07-03 15:22:16 +0800] [2676] [INFO] Booting worker with pid: 2676
[2020-07-03 15:22:16 +0800] [2677] [INFO] Booting worker with pid: 2677
[2020-07-03 15:22:16 +0800] [2680] [INFO] Booting worker with pid: 2680
[2020-07-03 15:22:16 +0800] [2668] [INFO] Handling signal: term
[2020-07-03 15:22:16 +0800] [2674] [INFO] Worker exiting (pid: 2674)
[2020-07-03 15:22:17 +0800] [2676] [INFO] Worker exiting (pid: 2676)
[2020-07-03 15:22:17 +0800] [2677] [INFO] Worker exiting (pid: 2677)
[2020-07-03 15:22:17 +0800] [2680] [INFO] Worker exiting (pid: 2680)
[2020-07-03 15:22:17 +0800] [2668] [INFO] Shutting down: Master
[2020-07-03 15:22:19 +0800] [2682] [INFO] Starting gunicorn 20.0.4
[2020-07-03 15:22:19 +0800] [2682] [INFO] Listening at: http://0.0.0.0:8002 (2682)
[2020-07-03 15:22:19 +0800] [2682] [INFO] Using worker: sync
[2020-07-03 15:22:19 +0800] [2688] [INFO] Booting worker with pid: 2688
[2020-07-03 15:22:19 +0800] [2690] [INFO] Booting worker with pid: 2690
[2020-07-03 15:22:19 +0800] [2692] [INFO] Booting worker with pid: 2692
[2020-07-03 15:22:20 +0800] [2693] [INFO] Booting worker with pid: 2693
/home/fms/project/venv/lib/python3.7/site-packages/pymysql/cursors.py:170: Warning: (1366, "Incorrect string value: '\\xD6\\xD0\\xB9\\xFA\\xB1\\xEA...' for column 'VARIABLE_VALUE' at row 480")
  result = self._query(query)
[2020-07-03 15:25:26,634] ERROR in app: Exception on /put [POST]
Traceback (most recent call last):
  File "/home/fms/project/venv/lib/python3.7/site-packages/sqlalchemy/engine/base.py", line 1278, in _execute_context
    cursor, statement, parameters, context
  File "/home/fms/project/venv/lib/python3.7/site-packages/sqlalchemy/engine/default.py", line 593, in do_execute
    cursor.execute(statement, parameters)
  File "/home/fms/project/venv/lib/python3.7/site-packages/pymysql/cursors.py", line 170, in execute
    result = self._query(query)
  File "/home/fms/project/venv/lib/python3.7/site-packages/pymysql/cursors.py", line 328, in _query
    conn.query(q)
  File "/home/fms/project/venv/lib/python3.7/site-packages/pymysql/connections.py", line 517, in query
    self._affected_rows = self._read_query_result(unbuffered=unbuffered)
  File "/home/fms/project/venv/lib/python3.7/site-packages/pymysql/connections.py", line 732, in _read_query_result
    result.read()
  File "/home/fms/project/venv/lib/python3.7/site-packages/pymysql/connections.py", line 1075, in read
    first_packet = self.connection._read_packet()
  File "/home/fms/project/venv/lib/python3.7/site-packages/pymysql/connections.py", line 684, in _read_packet
    packet.check_error()
  File "/home/fms/project/venv/lib/python3.7/site-packages/pymysql/protocol.py", line 220, in check_error
    err.raise_mysql_exception(self._data)
  File "/home/fms/project/venv/lib/python3.7/site-packages/pymysql/err.py", line 109, in raise_mysql_exception
    raise errorclass(errno, errval)
pymysql.err.DataError: (1406, "Data too long for column '经度' at row 1")

The above exception was the direct cause of the following exception:

Traceback (most recent call last):
  File "/home/fms/project/venv/lib/python3.7/site-packages/flask/app.py", line 2447, in wsgi_app
    response = self.full_dispatch_request()
  File "/home/fms/project/venv/lib/python3.7/site-packages/flask/app.py", line 1952, in full_dispatch_request
    rv = self.handle_user_exception(e)
  File "/home/fms/project/venv/lib/python3.7/site-packages/flask/app.py", line 1821, in handle_user_exception
    reraise(exc_type, exc_value, tb)
  File "/home/fms/project/venv/lib/python3.7/site-packages/flask/_compat.py", line 39, in reraise
    raise value
  File "/home/fms/project/venv/lib/python3.7/site-packages/flask/app.py", line 1950, in full_dispatch_request
    rv = self.dispatch_request()
  File "/home/fms/project/venv/lib/python3.7/site-packages/flask/app.py", line 1936, in dispatch_request
    return self.view_functions[rule.endpoint](**req.view_args)
  File "/home/fms/project/work2database/app.py", line 108, in put2datebase
    put2base(complaint_info, session_tousu)
  File "/home/fms/project/work2database/func.py", line 65, in put2base
    session3.commit()
  File "/home/fms/project/venv/lib/python3.7/site-packages/sqlalchemy/orm/session.py", line 1042, in commit
    self.transaction.commit()
  File "/home/fms/project/venv/lib/python3.7/site-packages/sqlalchemy/orm/session.py", line 504, in commit
    self._prepare_impl()
  File "/home/fms/project/venv/lib/python3.7/site-packages/sqlalchemy/orm/session.py", line 483, in _prepare_impl
    self.session.flush()
  File "/home/fms/project/venv/lib/python3.7/site-packages/sqlalchemy/orm/session.py", line 2523, in flush
    self._flush(objects)
  File "/home/fms/project/venv/lib/python3.7/site-packages/sqlalchemy/orm/session.py", line 2664, in _flush
    transaction.rollback(_capture_exception=True)
  File "/home/fms/project/venv/lib/python3.7/site-packages/sqlalchemy/util/langhelpers.py", line 69, in __exit__
    exc_value, with_traceback=exc_tb,
  File "/home/fms/project/venv/lib/python3.7/site-packages/sqlalchemy/util/compat.py", line 178, in raise_
    raise exception
  File "/home/fms/project/venv/lib/python3.7/site-packages/sqlalchemy/orm/session.py", line 2624, in _flush
    flush_context.execute()
  File "/home/fms/project/venv/lib/python3.7/site-packages/sqlalchemy/orm/unitofwork.py", line 422, in execute
    rec.execute(self)
  File "/home/fms/project/venv/lib/python3.7/site-packages/sqlalchemy/orm/unitofwork.py", line 589, in execute
    uow,
  File "/home/fms/project/venv/lib/python3.7/site-packages/sqlalchemy/orm/persistence.py", line 245, in save_obj
    insert,
  File "/home/fms/project/venv/lib/python3.7/site-packages/sqlalchemy/orm/persistence.py", line 1083, in _emit_insert_statements
    c = cached_connections[connection].execute(statement, multiparams)
  File "/home/fms/project/venv/lib/python3.7/site-packages/sqlalchemy/engine/base.py", line 1014, in execute
    return meth(self, multiparams, params)
  File "/home/fms/project/venv/lib/python3.7/site-packages/sqlalchemy/sql/elements.py", line 298, in _execute_on_connection
    return connection._execute_clauseelement(self, multiparams, params)
  File "/home/fms/project/venv/lib/python3.7/site-packages/sqlalchemy/engine/base.py", line 1133, in _execute_clauseelement
    distilled_params,
  File "/home/fms/project/venv/lib/python3.7/site-packages/sqlalchemy/engine/base.py", line 1318, in _execute_context
    e, statement, parameters, cursor, context
  File "/home/fms/project/venv/lib/python3.7/site-packages/sqlalchemy/engine/base.py", line 1512, in _handle_dbapi_exception
    sqlalchemy_exception, with_traceback=exc_info[2], from_=e
  File "/home/fms/project/venv/lib/python3.7/site-packages/sqlalchemy/util/compat.py", line 178, in raise_
    raise exception
  File "/home/fms/project/venv/lib/python3.7/site-packages/sqlalchemy/engine/base.py", line 1278, in _execute_context
    cursor, statement, parameters, context
  File "/home/fms/project/venv/lib/python3.7/site-packages/sqlalchemy/engine/default.py", line 593, in do_execute
    cursor.execute(statement, parameters)
  File "/home/fms/project/venv/lib/python3.7/site-packages/pymysql/cursors.py", line 170, in execute
    result = self._query(query)
  File "/home/fms/project/venv/lib/python3.7/site-packages/pymysql/cursors.py", line 328, in _query
    conn.query(q)
  File "/home/fms/project/venv/lib/python3.7/site-packages/pymysql/connections.py", line 517, in query
    self._affected_rows = self._read_query_result(unbuffered=unbuffered)
  File "/home/fms/project/venv/lib/python3.7/site-packages/pymysql/connections.py", line 732, in _read_query_result
    result.read()
  File "/home/fms/project/venv/lib/python3.7/site-packages/pymysql/connections.py", line 1075, in read
    first_packet = self.connection._read_packet()
  File "/home/fms/project/venv/lib/python3.7/site-packages/pymysql/connections.py", line 684, in _read_packet
    packet.check_error()
  File "/home/fms/project/venv/lib/python3.7/site-packages/pymysql/protocol.py", line 220, in check_error
    err.raise_mysql_exception(self._data)
  File "/home/fms/project/venv/lib/python3.7/site-packages/pymysql/err.py", line 109, in raise_mysql_exception
    raise errorclass(errno, errval)
sqlalchemy.exc.DataError: (pymysql.err.DataError) (1406, "Data too long for column '经度' at row 1")
[SQL: INSERT INTO tousu (`工单流水号`, `投诉内容`, `处理结果`, `我方办结原因`, `区县`, `乡镇`, `关联自然村_小区名`, `经度`, `纬度`, `关联基站代码`, `关联基站名称`, `投诉大类`, `投诉原因`, `网络类型`, `区域`, `区域细类`, `解决措施`, `解决措施_详`) VALUES (%(工单流水号)s, %(投诉内容)s, %(处理结果)s, %(我方办结原因)s, %(区县)s, %(乡镇)s, %(关联自然村_小区名)s, %(经度)s, %(纬度)s, %(关联基站代码)s, %(关联基站名称)s, %(投诉大类)s, %(投诉原因)s, %(网络类型)s, %(区域)s, %(区域细类)s, %(解决措施)s, %(解决措施_详)s)]
[parameters: {'工单流水号': 'TZ0000202007027855426', '投诉内容': 'CRM是否停机（共通）:在用\r\nHLR一键位置刷新:操作成功\r\nHLR是否开通:已开通\r\n询问手机上是否有“无服务”、“检测UIM卡”等提示:否\r\n询问用户周围是否有其他用户使用:不清楚\r\n其他的地方使用是否正常:是\r\n故障时间：2020.07.01-2020.07.02\r\n故障地址：云南省曲靖市沾益县菱角乡旧屋鲁村委会冷水沟村19号\r\n问题描述：（故障时间、用户状态等）用户反映没有正常的手机信号，更换手机。插拔电话卡都无法正常使用网络信号。\r\n手机机型\r\n用户要求：核实情况恢复正常手机信号使用。', '处理结果': '投诉产生原因：弱覆盖\r\n经过核实，用户投诉地点：冷水沟村属自然村场景，当地无基站，用户距离我方最近的基站__沾益区菱角乡卜嘎村基站，3.2_km，已经超出4G网络覆盖范围所以会出现信号弱不稳定的情况，从我方掌握的基站信息结合用户的地理位置已经可以判断当地属于弱覆盖，所以无需进行现场测试。当地的网络覆盖需要新建基站才能改善，目前省公司暂无建设投资计划，分公司只能执行省公司的建设计划，所以我方也无法给出具体解决时间。', '我方办结原因': '弱覆盖', '区县': '沾益', '乡镇': '', '关联自然村_小区名': '冷水沟村', '经度': ' 103.815565', '纬度': '25.856289', '关联基站代码': '', '关联基站名称': '', '投诉大类': None, '投诉原因': None, '网络类型': None, '区域': '农村', '区域细类': '自然村', '解决措施': '基站建设', '解决措施_详': None}]
(Background on this error at: http://sqlalche.me/e/13/9h9h)
[2020-07-03 15:25:36 +0800] [2682] [INFO] Handling signal: term
[2020-07-03 15:25:36 +0800] [2688] [INFO] Worker exiting (pid: 2688)
[2020-07-03 15:25:36 +0800] [2690] [INFO] Worker exiting (pid: 2690)
[2020-07-03 15:25:36 +0800] [2692] [INFO] Worker exiting (pid: 2692)
[2020-07-03 15:25:36 +0800] [2693] [INFO] Worker exiting (pid: 2693)
[2020-07-03 15:25:38 +0800] [2682] [INFO] Shutting down: Master
[2020-07-03 15:25:40 +0800] [2697] [INFO] Starting gunicorn 20.0.4
[2020-07-03 15:25:40 +0800] [2697] [INFO] Listening at: http://0.0.0.0:8002 (2697)
[2020-07-03 15:25:40 +0800] [2697] [INFO] Using worker: sync
[2020-07-03 15:25:40 +0800] [2703] [INFO] Booting worker with pid: 2703
[2020-07-03 15:25:40 +0800] [2704] [INFO] Booting worker with pid: 2704
[2020-07-03 15:25:40 +0800] [2705] [INFO] Booting worker with pid: 2705
[2020-07-03 15:25:40 +0800] [2707] [INFO] Booting worker with pid: 2707
/home/fms/project/venv/lib/python3.7/site-packages/pymysql/cursors.py:170: Warning: (1366, "Incorrect string value: '\\xD6\\xD0\\xB9\\xFA\\xB1\\xEA...' for column 'VARIABLE_VALUE' at row 480")
  result = self._query(query)
[2020-07-03 15:26:41,830] ERROR in app: Exception on /put [POST]
Traceback (most recent call last):
  File "/home/fms/project/venv/lib/python3.7/site-packages/sqlalchemy/engine/base.py", line 1278, in _execute_context
    cursor, statement, parameters, context
  File "/home/fms/project/venv/lib/python3.7/site-packages/sqlalchemy/engine/default.py", line 593, in do_execute
    cursor.execute(statement, parameters)
  File "/home/fms/project/venv/lib/python3.7/site-packages/pymysql/cursors.py", line 170, in execute
    result = self._query(query)
  File "/home/fms/project/venv/lib/python3.7/site-packages/pymysql/cursors.py", line 328, in _query
    conn.query(q)
  File "/home/fms/project/venv/lib/python3.7/site-packages/pymysql/connections.py", line 517, in query
    self._affected_rows = self._read_query_result(unbuffered=unbuffered)
  File "/home/fms/project/venv/lib/python3.7/site-packages/pymysql/connections.py", line 732, in _read_query_result
    result.read()
  File "/home/fms/project/venv/lib/python3.7/site-packages/pymysql/connections.py", line 1075, in read
    first_packet = self.connection._read_packet()
  File "/home/fms/project/venv/lib/python3.7/site-packages/pymysql/connections.py", line 684, in _read_packet
    packet.check_error()
  File "/home/fms/project/venv/lib/python3.7/site-packages/pymysql/protocol.py", line 220, in check_error
    err.raise_mysql_exception(self._data)
  File "/home/fms/project/venv/lib/python3.7/site-packages/pymysql/err.py", line 109, in raise_mysql_exception
    raise errorclass(errno, errval)
pymysql.err.DataError: (1406, "Data too long for column '经度' at row 1")

The above exception was the direct cause of the following exception:

Traceback (most recent call last):
  File "/home/fms/project/venv/lib/python3.7/site-packages/flask/app.py", line 2447, in wsgi_app
    response = self.full_dispatch_request()
  File "/home/fms/project/venv/lib/python3.7/site-packages/flask/app.py", line 1952, in full_dispatch_request
    rv = self.handle_user_exception(e)
  File "/home/fms/project/venv/lib/python3.7/site-packages/flask/app.py", line 1821, in handle_user_exception
    reraise(exc_type, exc_value, tb)
  File "/home/fms/project/venv/lib/python3.7/site-packages/flask/_compat.py", line 39, in reraise
    raise value
  File "/home/fms/project/venv/lib/python3.7/site-packages/flask/app.py", line 1950, in full_dispatch_request
    rv = self.dispatch_request()
  File "/home/fms/project/venv/lib/python3.7/site-packages/flask/app.py", line 1936, in dispatch_request
    return self.view_functions[rule.endpoint](**req.view_args)
  File "/home/fms/project/work2database/app.py", line 108, in put2datebase
    put2base(complaint_info, session_tousu)
  File "/home/fms/project/work2database/func.py", line 65, in put2base
    session3.commit()
  File "/home/fms/project/venv/lib/python3.7/site-packages/sqlalchemy/orm/session.py", line 1042, in commit
    self.transaction.commit()
  File "/home/fms/project/venv/lib/python3.7/site-packages/sqlalchemy/orm/session.py", line 504, in commit
    self._prepare_impl()
  File "/home/fms/project/venv/lib/python3.7/site-packages/sqlalchemy/orm/session.py", line 483, in _prepare_impl
    self.session.flush()
  File "/home/fms/project/venv/lib/python3.7/site-packages/sqlalchemy/orm/session.py", line 2523, in flush
    self._flush(objects)
  File "/home/fms/project/venv/lib/python3.7/site-packages/sqlalchemy/orm/session.py", line 2664, in _flush
    transaction.rollback(_capture_exception=True)
  File "/home/fms/project/venv/lib/python3.7/site-packages/sqlalchemy/util/langhelpers.py", line 69, in __exit__
    exc_value, with_traceback=exc_tb,
  File "/home/fms/project/venv/lib/python3.7/site-packages/sqlalchemy/util/compat.py", line 178, in raise_
    raise exception
  File "/home/fms/project/venv/lib/python3.7/site-packages/sqlalchemy/orm/session.py", line 2624, in _flush
    flush_context.execute()
  File "/home/fms/project/venv/lib/python3.7/site-packages/sqlalchemy/orm/unitofwork.py", line 422, in execute
    rec.execute(self)
  File "/home/fms/project/venv/lib/python3.7/site-packages/sqlalchemy/orm/unitofwork.py", line 589, in execute
    uow,
  File "/home/fms/project/venv/lib/python3.7/site-packages/sqlalchemy/orm/persistence.py", line 245, in save_obj
    insert,
  File "/home/fms/project/venv/lib/python3.7/site-packages/sqlalchemy/orm/persistence.py", line 1083, in _emit_insert_statements
    c = cached_connections[connection].execute(statement, multiparams)
  File "/home/fms/project/venv/lib/python3.7/site-packages/sqlalchemy/engine/base.py", line 1014, in execute
    return meth(self, multiparams, params)
  File "/home/fms/project/venv/lib/python3.7/site-packages/sqlalchemy/sql/elements.py", line 298, in _execute_on_connection
    return connection._execute_clauseelement(self, multiparams, params)
  File "/home/fms/project/venv/lib/python3.7/site-packages/sqlalchemy/engine/base.py", line 1133, in _execute_clauseelement
    distilled_params,
  File "/home/fms/project/venv/lib/python3.7/site-packages/sqlalchemy/engine/base.py", line 1318, in _execute_context
    e, statement, parameters, cursor, context
  File "/home/fms/project/venv/lib/python3.7/site-packages/sqlalchemy/engine/base.py", line 1512, in _handle_dbapi_exception
    sqlalchemy_exception, with_traceback=exc_info[2], from_=e
  File "/home/fms/project/venv/lib/python3.7/site-packages/sqlalchemy/util/compat.py", line 178, in raise_
    raise exception
  File "/home/fms/project/venv/lib/python3.7/site-packages/sqlalchemy/engine/base.py", line 1278, in _execute_context
    cursor, statement, parameters, context
  File "/home/fms/project/venv/lib/python3.7/site-packages/sqlalchemy/engine/default.py", line 593, in do_execute
    cursor.execute(statement, parameters)
  File "/home/fms/project/venv/lib/python3.7/site-packages/pymysql/cursors.py", line 170, in execute
    result = self._query(query)
  File "/home/fms/project/venv/lib/python3.7/site-packages/pymysql/cursors.py", line 328, in _query
    conn.query(q)
  File "/home/fms/project/venv/lib/python3.7/site-packages/pymysql/connections.py", line 517, in query
    self._affected_rows = self._read_query_result(unbuffered=unbuffered)
  File "/home/fms/project/venv/lib/python3.7/site-packages/pymysql/connections.py", line 732, in _read_query_result
    result.read()
  File "/home/fms/project/venv/lib/python3.7/site-packages/pymysql/connections.py", line 1075, in read
    first_packet = self.connection._read_packet()
  File "/home/fms/project/venv/lib/python3.7/site-packages/pymysql/connections.py", line 684, in _read_packet
    packet.check_error()
  File "/home/fms/project/venv/lib/python3.7/site-packages/pymysql/protocol.py", line 220, in check_error
    err.raise_mysql_exception(self._data)
  File "/home/fms/project/venv/lib/python3.7/site-packages/pymysql/err.py", line 109, in raise_mysql_exception
    raise errorclass(errno, errval)
sqlalchemy.exc.DataError: (pymysql.err.DataError) (1406, "Data too long for column '经度' at row 1")
[SQL: INSERT INTO tousu (`工单流水号`, `投诉内容`, `处理结果`, `我方办结原因`, `区县`, `乡镇`, `关联自然村_小区名`, `经度`, `纬度`, `关联基站代码`, `关联基站名称`, `投诉大类`, `投诉原因`, `网络类型`, `区域`, `区域细类`, `解决措施`, `解决措施_详`) VALUES (%(工单流水号)s, %(投诉内容)s, %(处理结果)s, %(我方办结原因)s, %(区县)s, %(乡镇)s, %(关联自然村_小区名)s, %(经度)s, %(纬度)s, %(关联基站代码)s, %(关联基站名称)s, %(投诉大类)s, %(投诉原因)s, %(网络类型)s, %(区域)s, %(区域细类)s, %(解决措施)s, %(解决措施_详)s)]
[parameters: {'工单流水号': 'TZ0000202007027855426', '投诉内容': 'CRM是否停机（共通）:在用\r\nHLR一键位置刷新:操作成功\r\nHLR是否开通:已开通\r\n询问手机上是否有“无服务”、“检测UIM卡”等提示:否\r\n询问用户周围是否有其他用户使用:不清楚\r\n其他的地方使用是否正常:是\r\n故障时间：2020.07.01-2020.07.02\r\n故障地址：云南省曲靖市沾益县菱角乡旧屋鲁村委会冷水沟村19号\r\n问题描述：（故障时间、用户状态等）用户反映没有正常的手机信号，更换手机。插拔电话卡都无法正常使用网络信号。\r\n手机机型\r\n用户要求：核实情况恢复正常手机信号使用。', '处理结果': '投诉产生原因：弱覆盖\r\n经过核实，用户投诉地点：冷水沟村属自然村场景，当地无基站，用户距离我方最近的基站__沾益区菱角乡卜嘎村基站，3.2_km，已经超出4G网络覆盖范围所以会出现信号弱不稳定的情况，从我方掌握的基站信息结合用户的地理位置已经可以判断当地属于弱覆盖，所以无需进行现场测试。当地的网络覆盖需要新建基站才能改善，目前省公司暂无建设投资计划，分公司只能执行省公司的建设计划，所以我方也无法给出具体解决时间。', '我方办结原因': '弱覆盖', '区县': '沾益', '乡镇': '', '关联自然村_小区名': '冷水沟村', '经度': ' 103.815565', '纬度': '25.856289', '关联基站代码': '', '关联基站名称': '', '投诉大类': None, '投诉原因': None, '网络类型': None, '区域': '农村', '区域细类': '自然村', '解决措施': '基站建设', '解决措施_详': None}]
(Background on this error at: http://sqlalche.me/e/13/9h9h)
[2020-07-03 15:26:58 +0800] [2697] [INFO] Handling signal: term
[2020-07-03 15:26:58 +0800] [2705] [INFO] Worker exiting (pid: 2705)
[2020-07-03 15:26:58 +0800] [2704] [INFO] Worker exiting (pid: 2704)
[2020-07-03 15:26:58 +0800] [2703] [INFO] Worker exiting (pid: 2703)
[2020-07-03 15:26:58 +0800] [2707] [INFO] Worker exiting (pid: 2707)
[2020-07-03 15:26:58 +0800] [2697] [INFO] Shutting down: Master
[2020-07-03 15:27:01 +0800] [2712] [INFO] Starting gunicorn 20.0.4
[2020-07-03 15:27:01 +0800] [2712] [INFO] Listening at: http://0.0.0.0:8002 (2712)
[2020-07-03 15:27:01 +0800] [2712] [INFO] Using worker: sync
[2020-07-03 15:27:01 +0800] [2718] [INFO] Booting worker with pid: 2718
[2020-07-03 15:27:01 +0800] [2721] [INFO] Booting worker with pid: 2721
[2020-07-03 15:27:01 +0800] [2723] [INFO] Booting worker with pid: 2723
[2020-07-03 15:27:01 +0800] [2724] [INFO] Booting worker with pid: 2724
[2020-07-03 15:27:12 +0800] [2712] [INFO] Handling signal: term
[2020-07-03 15:27:12 +0800] [2718] [INFO] Worker exiting (pid: 2718)
[2020-07-03 15:27:12 +0800] [2723] [INFO] Worker exiting (pid: 2723)
[2020-07-03 15:27:12 +0800] [2721] [INFO] Worker exiting (pid: 2721)
[2020-07-03 15:27:12 +0800] [2724] [INFO] Worker exiting (pid: 2724)
[2020-07-03 15:27:12 +0800] [2712] [INFO] Shutting down: Master
[2020-07-03 15:27:14 +0800] [2726] [INFO] Starting gunicorn 20.0.4
[2020-07-03 15:27:14 +0800] [2726] [INFO] Listening at: http://0.0.0.0:8002 (2726)
[2020-07-03 15:27:14 +0800] [2726] [INFO] Using worker: sync
[2020-07-03 15:27:14 +0800] [2732] [INFO] Booting worker with pid: 2732
[2020-07-03 15:27:14 +0800] [2733] [INFO] Booting worker with pid: 2733
[2020-07-03 15:27:14 +0800] [2734] [INFO] Booting worker with pid: 2734
[2020-07-03 15:27:15 +0800] [2737] [INFO] Booting worker with pid: 2737
/home/fms/project/venv/lib/python3.7/site-packages/pymysql/cursors.py:170: Warning: (1366, "Incorrect string value: '\\xD6\\xD0\\xB9\\xFA\\xB1\\xEA...' for column 'VARIABLE_VALUE' at row 480")
  result = self._query(query)
[2020-07-03 15:27:57,549] ERROR in app: Exception on /put [POST]
Traceback (most recent call last):
  File "/home/fms/project/venv/lib/python3.7/site-packages/sqlalchemy/engine/base.py", line 1278, in _execute_context
    cursor, statement, parameters, context
  File "/home/fms/project/venv/lib/python3.7/site-packages/sqlalchemy/engine/default.py", line 593, in do_execute
    cursor.execute(statement, parameters)
  File "/home/fms/project/venv/lib/python3.7/site-packages/pymysql/cursors.py", line 170, in execute
    result = self._query(query)
  File "/home/fms/project/venv/lib/python3.7/site-packages/pymysql/cursors.py", line 328, in _query
    conn.query(q)
  File "/home/fms/project/venv/lib/python3.7/site-packages/pymysql/connections.py", line 517, in query
    self._affected_rows = self._read_query_result(unbuffered=unbuffered)
  File "/home/fms/project/venv/lib/python3.7/site-packages/pymysql/connections.py", line 732, in _read_query_result
    result.read()
  File "/home/fms/project/venv/lib/python3.7/site-packages/pymysql/connections.py", line 1075, in read
    first_packet = self.connection._read_packet()
  File "/home/fms/project/venv/lib/python3.7/site-packages/pymysql/connections.py", line 684, in _read_packet
    packet.check_error()
  File "/home/fms/project/venv/lib/python3.7/site-packages/pymysql/protocol.py", line 220, in check_error
    err.raise_mysql_exception(self._data)
  File "/home/fms/project/venv/lib/python3.7/site-packages/pymysql/err.py", line 109, in raise_mysql_exception
    raise errorclass(errno, errval)
pymysql.err.DataError: (1406, "Data too long for column '经度' at row 1")

The above exception was the direct cause of the following exception:

Traceback (most recent call last):
  File "/home/fms/project/venv/lib/python3.7/site-packages/flask/app.py", line 2447, in wsgi_app
    response = self.full_dispatch_request()
  File "/home/fms/project/venv/lib/python3.7/site-packages/flask/app.py", line 1952, in full_dispatch_request
    rv = self.handle_user_exception(e)
  File "/home/fms/project/venv/lib/python3.7/site-packages/flask/app.py", line 1821, in handle_user_exception
    reraise(exc_type, exc_value, tb)
  File "/home/fms/project/venv/lib/python3.7/site-packages/flask/_compat.py", line 39, in reraise
    raise value
  File "/home/fms/project/venv/lib/python3.7/site-packages/flask/app.py", line 1950, in full_dispatch_request
    rv = self.dispatch_request()
  File "/home/fms/project/venv/lib/python3.7/site-packages/flask/app.py", line 1936, in dispatch_request
    return self.view_functions[rule.endpoint](**req.view_args)
  File "/home/fms/project/work2database/app.py", line 108, in put2datebase
    put2base(complaint_info, session_tousu)
  File "/home/fms/project/work2database/func.py", line 65, in put2base
    session3.commit()
  File "/home/fms/project/venv/lib/python3.7/site-packages/sqlalchemy/orm/session.py", line 1042, in commit
    self.transaction.commit()
  File "/home/fms/project/venv/lib/python3.7/site-packages/sqlalchemy/orm/session.py", line 504, in commit
    self._prepare_impl()
  File "/home/fms/project/venv/lib/python3.7/site-packages/sqlalchemy/orm/session.py", line 483, in _prepare_impl
    self.session.flush()
  File "/home/fms/project/venv/lib/python3.7/site-packages/sqlalchemy/orm/session.py", line 2523, in flush
    self._flush(objects)
  File "/home/fms/project/venv/lib/python3.7/site-packages/sqlalchemy/orm/session.py", line 2664, in _flush
    transaction.rollback(_capture_exception=True)
  File "/home/fms/project/venv/lib/python3.7/site-packages/sqlalchemy/util/langhelpers.py", line 69, in __exit__
    exc_value, with_traceback=exc_tb,
  File "/home/fms/project/venv/lib/python3.7/site-packages/sqlalchemy/util/compat.py", line 178, in raise_
    raise exception
  File "/home/fms/project/venv/lib/python3.7/site-packages/sqlalchemy/orm/session.py", line 2624, in _flush
    flush_context.execute()
  File "/home/fms/project/venv/lib/python3.7/site-packages/sqlalchemy/orm/unitofwork.py", line 422, in execute
    rec.execute(self)
  File "/home/fms/project/venv/lib/python3.7/site-packages/sqlalchemy/orm/unitofwork.py", line 589, in execute
    uow,
  File "/home/fms/project/venv/lib/python3.7/site-packages/sqlalchemy/orm/persistence.py", line 245, in save_obj
    insert,
  File "/home/fms/project/venv/lib/python3.7/site-packages/sqlalchemy/orm/persistence.py", line 1083, in _emit_insert_statements
    c = cached_connections[connection].execute(statement, multiparams)
  File "/home/fms/project/venv/lib/python3.7/site-packages/sqlalchemy/engine/base.py", line 1014, in execute
    return meth(self, multiparams, params)
  File "/home/fms/project/venv/lib/python3.7/site-packages/sqlalchemy/sql/elements.py", line 298, in _execute_on_connection
    return connection._execute_clauseelement(self, multiparams, params)
  File "/home/fms/project/venv/lib/python3.7/site-packages/sqlalchemy/engine/base.py", line 1133, in _execute_clauseelement
    distilled_params,
  File "/home/fms/project/venv/lib/python3.7/site-packages/sqlalchemy/engine/base.py", line 1318, in _execute_context
    e, statement, parameters, cursor, context
  File "/home/fms/project/venv/lib/python3.7/site-packages/sqlalchemy/engine/base.py", line 1512, in _handle_dbapi_exception
    sqlalchemy_exception, with_traceback=exc_info[2], from_=e
  File "/home/fms/project/venv/lib/python3.7/site-packages/sqlalchemy/util/compat.py", line 178, in raise_
    raise exception
  File "/home/fms/project/venv/lib/python3.7/site-packages/sqlalchemy/engine/base.py", line 1278, in _execute_context
    cursor, statement, parameters, context
  File "/home/fms/project/venv/lib/python3.7/site-packages/sqlalchemy/engine/default.py", line 593, in do_execute
    cursor.execute(statement, parameters)
  File "/home/fms/project/venv/lib/python3.7/site-packages/pymysql/cursors.py", line 170, in execute
    result = self._query(query)
  File "/home/fms/project/venv/lib/python3.7/site-packages/pymysql/cursors.py", line 328, in _query
    conn.query(q)
  File "/home/fms/project/venv/lib/python3.7/site-packages/pymysql/connections.py", line 517, in query
    self._affected_rows = self._read_query_result(unbuffered=unbuffered)
  File "/home/fms/project/venv/lib/python3.7/site-packages/pymysql/connections.py", line 732, in _read_query_result
    result.read()
  File "/home/fms/project/venv/lib/python3.7/site-packages/pymysql/connections.py", line 1075, in read
    first_packet = self.connection._read_packet()
  File "/home/fms/project/venv/lib/python3.7/site-packages/pymysql/connections.py", line 684, in _read_packet
    packet.check_error()
  File "/home/fms/project/venv/lib/python3.7/site-packages/pymysql/protocol.py", line 220, in check_error
    err.raise_mysql_exception(self._data)
  File "/home/fms/project/venv/lib/python3.7/site-packages/pymysql/err.py", line 109, in raise_mysql_exception
    raise errorclass(errno, errval)
sqlalchemy.exc.DataError: (pymysql.err.DataError) (1406, "Data too long for column '经度' at row 1")
[SQL: INSERT INTO tousu (`工单流水号`, `投诉内容`, `处理结果`, `我方办结原因`, `区县`, `乡镇`, `关联自然村_小区名`, `经度`, `纬度`, `关联基站代码`, `关联基站名称`, `投诉大类`, `投诉原因`, `网络类型`, `区域`, `区域细类`, `解决措施`, `解决措施_详`) VALUES (%(工单流水号)s, %(投诉内容)s, %(处理结果)s, %(我方办结原因)s, %(区县)s, %(乡镇)s, %(关联自然村_小区名)s, %(经度)s, %(纬度)s, %(关联基站代码)s, %(关联基站名称)s, %(投诉大类)s, %(投诉原因)s, %(网络类型)s, %(区域)s, %(区域细类)s, %(解决措施)s, %(解决措施_详)s)]
[parameters: {'工单流水号': 'TZ0000202007027855426', '投诉内容': 'CRM是否停机（共通）:在用\r\nHLR一键位置刷新:操作成功\r\nHLR是否开通:已开通\r\n询问手机上是否有“无服务”、“检测UIM卡”等提示:否\r\n询问用户周围是否有其他用户使用:不清楚\r\n其他的地方使用是否正常:是\r\n故障时间：2020.07.01-2020.07.02\r\n故障地址：云南省曲靖市沾益县菱角乡旧屋鲁村委会冷水沟村19号\r\n问题描述：（故障时间、用户状态等）用户反映没有正常的手机信号，更换手机。插拔电话卡都无法正常使用网络信号。\r\n手机机型\r\n用户要求：核实情况恢复正常手机信号使用。', '处理结果': '投诉产生原因：弱覆盖\r\n经过核实，用户投诉地点：冷水沟村属自然村场景，当地无基站，用户距离我方最近的基站__沾益区菱角乡卜嘎村基站，3.2_km，已经超出4G网络覆盖范围所以会出现信号弱不稳定的情况，从我方掌握的基站信息结合用户的地理位置已经可以判断当地属于弱覆盖，所以无需进行现场测试。当地的网络覆盖需要新建基站才能改善，目前省公司暂无建设投资计划，分公司只能执行省公司的建设计划，所以我方也无法给出具体解决时间。', '我方办结原因': '弱覆盖', '区县': '沾益', '乡镇': '', '关联自然村_小区名': '冷水沟村', '经度': ' 103.815565', '纬度': '25.856289', '关联基站代码': '', '关联基站名称': '', '投诉大类': None, '投诉原因': None, '网络类型': None, '区域': '农村', '区域细类': '自然村', '解决措施': '基站建设', '解决措施_详': None}]
(Background on this error at: http://sqlalche.me/e/13/9h9h)
[2020-07-03 15:28:13 +0800] [2726] [INFO] Handling signal: term
/home/fms/project/venv/lib/python3.7/site-packages/pymysql/cursors.py:170: Warning: (1366, "Incorrect string value: '\\xD6\\xD0\\xB9\\xFA\\xB1\\xEA...' for column 'VARIABLE_VALUE' at row 480")
  result = self._query(query)
[2020-07-03 15:28:13 +0800] [2734] [INFO] Worker exiting (pid: 2734)
[2020-07-03 15:28:13 +0800] [2732] [INFO] Worker exiting (pid: 2732)
/home/fms/project/venv/lib/python3.7/site-packages/pymysql/cursors.py:170: Warning: (1366, "Incorrect string value: '\\xD6\\xD0\\xB9\\xFA\\xB1\\xEA...' for column 'VARIABLE_VALUE' at row 480")
  result = self._query(query)
[2020-07-03 15:28:13 +0800] [2733] [INFO] Worker exiting (pid: 2733)
[2020-07-03 15:28:13 +0800] [2737] [INFO] Worker exiting (pid: 2737)
[2020-07-03 15:28:14 +0800] [2726] [INFO] Shutting down: Master
[2020-07-03 15:28:27 +0800] [2740] [INFO] Starting gunicorn 20.0.4
[2020-07-03 15:28:27 +0800] [2740] [INFO] Listening at: http://0.0.0.0:8002 (2740)
[2020-07-03 15:28:27 +0800] [2740] [INFO] Using worker: sync
[2020-07-03 15:28:27 +0800] [2746] [INFO] Booting worker with pid: 2746
[2020-07-03 15:28:27 +0800] [2748] [INFO] Booting worker with pid: 2748
[2020-07-03 15:28:28 +0800] [2750] [INFO] Booting worker with pid: 2750
[2020-07-03 15:28:28 +0800] [2752] [INFO] Booting worker with pid: 2752
[2020-07-03 15:28:43 +0800] [2740] [INFO] Handling signal: term
[2020-07-03 15:28:43 +0800] [2746] [INFO] Worker exiting (pid: 2746)
[2020-07-03 15:28:43 +0800] [2752] [INFO] Worker exiting (pid: 2752)
[2020-07-03 15:28:43 +0800] [2750] [INFO] Worker exiting (pid: 2750)
[2020-07-03 15:28:43 +0800] [2748] [INFO] Worker exiting (pid: 2748)
[2020-07-03 15:28:44 +0800] [2740] [INFO] Shutting down: Master
[2020-07-03 15:28:48 +0800] [2754] [INFO] Starting gunicorn 20.0.4
[2020-07-03 15:28:48 +0800] [2754] [INFO] Listening at: http://0.0.0.0:8002 (2754)
[2020-07-03 15:28:48 +0800] [2754] [INFO] Using worker: sync
[2020-07-03 15:28:48 +0800] [2758] [INFO] Booting worker with pid: 2758
[2020-07-03 15:28:48 +0800] [2762] [INFO] Booting worker with pid: 2762
[2020-07-03 15:28:48 +0800] [2763] [INFO] Booting worker with pid: 2763
[2020-07-03 15:28:48 +0800] [2765] [INFO] Booting worker with pid: 2765
/home/fms/project/venv/lib/python3.7/site-packages/pymysql/cursors.py:170: Warning: (1366, "Incorrect string value: '\\xD6\\xD0\\xB9\\xFA\\xB1\\xEA...' for column 'VARIABLE_VALUE' at row 480")
  result = self._query(query)
[2020-07-03 15:49:54,384] ERROR in app: Exception on /put [POST]
Traceback (most recent call last):
  File "/home/fms/project/venv/lib/python3.7/site-packages/sqlalchemy/engine/base.py", line 1278, in _execute_context
    cursor, statement, parameters, context
  File "/home/fms/project/venv/lib/python3.7/site-packages/sqlalchemy/engine/default.py", line 593, in do_execute
    cursor.execute(statement, parameters)
  File "/home/fms/project/venv/lib/python3.7/site-packages/pymysql/cursors.py", line 170, in execute
    result = self._query(query)
  File "/home/fms/project/venv/lib/python3.7/site-packages/pymysql/cursors.py", line 328, in _query
    conn.query(q)
  File "/home/fms/project/venv/lib/python3.7/site-packages/pymysql/connections.py", line 517, in query
    self._affected_rows = self._read_query_result(unbuffered=unbuffered)
  File "/home/fms/project/venv/lib/python3.7/site-packages/pymysql/connections.py", line 732, in _read_query_result
    result.read()
  File "/home/fms/project/venv/lib/python3.7/site-packages/pymysql/connections.py", line 1075, in read
    first_packet = self.connection._read_packet()
  File "/home/fms/project/venv/lib/python3.7/site-packages/pymysql/connections.py", line 684, in _read_packet
    packet.check_error()
  File "/home/fms/project/venv/lib/python3.7/site-packages/pymysql/protocol.py", line 220, in check_error
    err.raise_mysql_exception(self._data)
  File "/home/fms/project/venv/lib/python3.7/site-packages/pymysql/err.py", line 109, in raise_mysql_exception
    raise errorclass(errno, errval)
pymysql.err.DataError: (1406, "Data too long for column '经度' at row 1")

The above exception was the direct cause of the following exception:

Traceback (most recent call last):
  File "/home/fms/project/venv/lib/python3.7/site-packages/flask/app.py", line 2447, in wsgi_app
    response = self.full_dispatch_request()
  File "/home/fms/project/venv/lib/python3.7/site-packages/flask/app.py", line 1952, in full_dispatch_request
    rv = self.handle_user_exception(e)
  File "/home/fms/project/venv/lib/python3.7/site-packages/flask/app.py", line 1821, in handle_user_exception
    reraise(exc_type, exc_value, tb)
  File "/home/fms/project/venv/lib/python3.7/site-packages/flask/_compat.py", line 39, in reraise
    raise value
  File "/home/fms/project/venv/lib/python3.7/site-packages/flask/app.py", line 1950, in full_dispatch_request
    rv = self.dispatch_request()
  File "/home/fms/project/venv/lib/python3.7/site-packages/flask/app.py", line 1936, in dispatch_request
    return self.view_functions[rule.endpoint](**req.view_args)
  File "/home/fms/project/work2database/app.py", line 108, in put2datebase
    put2base(complaint_info, session_tousu)
  File "/home/fms/project/work2database/func.py", line 65, in put2base
    session3.commit()
  File "/home/fms/project/venv/lib/python3.7/site-packages/sqlalchemy/orm/session.py", line 1042, in commit
    self.transaction.commit()
  File "/home/fms/project/venv/lib/python3.7/site-packages/sqlalchemy/orm/session.py", line 504, in commit
    self._prepare_impl()
  File "/home/fms/project/venv/lib/python3.7/site-packages/sqlalchemy/orm/session.py", line 483, in _prepare_impl
    self.session.flush()
  File "/home/fms/project/venv/lib/python3.7/site-packages/sqlalchemy/orm/session.py", line 2523, in flush
    self._flush(objects)
  File "/home/fms/project/venv/lib/python3.7/site-packages/sqlalchemy/orm/session.py", line 2664, in _flush
    transaction.rollback(_capture_exception=True)
  File "/home/fms/project/venv/lib/python3.7/site-packages/sqlalchemy/util/langhelpers.py", line 69, in __exit__
    exc_value, with_traceback=exc_tb,
  File "/home/fms/project/venv/lib/python3.7/site-packages/sqlalchemy/util/compat.py", line 178, in raise_
    raise exception
  File "/home/fms/project/venv/lib/python3.7/site-packages/sqlalchemy/orm/session.py", line 2624, in _flush
    flush_context.execute()
  File "/home/fms/project/venv/lib/python3.7/site-packages/sqlalchemy/orm/unitofwork.py", line 422, in execute
    rec.execute(self)
  File "/home/fms/project/venv/lib/python3.7/site-packages/sqlalchemy/orm/unitofwork.py", line 589, in execute
    uow,
  File "/home/fms/project/venv/lib/python3.7/site-packages/sqlalchemy/orm/persistence.py", line 245, in save_obj
    insert,
  File "/home/fms/project/venv/lib/python3.7/site-packages/sqlalchemy/orm/persistence.py", line 1083, in _emit_insert_statements
    c = cached_connections[connection].execute(statement, multiparams)
  File "/home/fms/project/venv/lib/python3.7/site-packages/sqlalchemy/engine/base.py", line 1014, in execute
    return meth(self, multiparams, params)
  File "/home/fms/project/venv/lib/python3.7/site-packages/sqlalchemy/sql/elements.py", line 298, in _execute_on_connection
    return connection._execute_clauseelement(self, multiparams, params)
  File "/home/fms/project/venv/lib/python3.7/site-packages/sqlalchemy/engine/base.py", line 1133, in _execute_clauseelement
    distilled_params,
  File "/home/fms/project/venv/lib/python3.7/site-packages/sqlalchemy/engine/base.py", line 1318, in _execute_context
    e, statement, parameters, cursor, context
  File "/home/fms/project/venv/lib/python3.7/site-packages/sqlalchemy/engine/base.py", line 1512, in _handle_dbapi_exception
    sqlalchemy_exception, with_traceback=exc_info[2], from_=e
  File "/home/fms/project/venv/lib/python3.7/site-packages/sqlalchemy/util/compat.py", line 178, in raise_
    raise exception
  File "/home/fms/project/venv/lib/python3.7/site-packages/sqlalchemy/engine/base.py", line 1278, in _execute_context
    cursor, statement, parameters, context
  File "/home/fms/project/venv/lib/python3.7/site-packages/sqlalchemy/engine/default.py", line 593, in do_execute
    cursor.execute(statement, parameters)
  File "/home/fms/project/venv/lib/python3.7/site-packages/pymysql/cursors.py", line 170, in execute
    result = self._query(query)
  File "/home/fms/project/venv/lib/python3.7/site-packages/pymysql/cursors.py", line 328, in _query
    conn.query(q)
  File "/home/fms/project/venv/lib/python3.7/site-packages/pymysql/connections.py", line 517, in query
    self._affected_rows = self._read_query_result(unbuffered=unbuffered)
  File "/home/fms/project/venv/lib/python3.7/site-packages/pymysql/connections.py", line 732, in _read_query_result
    result.read()
  File "/home/fms/project/venv/lib/python3.7/site-packages/pymysql/connections.py", line 1075, in read
    first_packet = self.connection._read_packet()
  File "/home/fms/project/venv/lib/python3.7/site-packages/pymysql/connections.py", line 684, in _read_packet
    packet.check_error()
  File "/home/fms/project/venv/lib/python3.7/site-packages/pymysql/protocol.py", line 220, in check_error
    err.raise_mysql_exception(self._data)
  File "/home/fms/project/venv/lib/python3.7/site-packages/pymysql/err.py", line 109, in raise_mysql_exception
    raise errorclass(errno, errval)
sqlalchemy.exc.DataError: (pymysql.err.DataError) (1406, "Data too long for column '经度' at row 1")
[SQL: INSERT INTO tousu (`工单流水号`, `投诉内容`, `处理结果`, `我方办结原因`, `区县`, `乡镇`, `关联自然村_小区名`, `经度`, `纬度`, `关联基站代码`, `关联基站名称`, `投诉大类`, `投诉原因`, `网络类型`, `区域`, `区域细类`, `解决措施`, `解决措施_详`) VALUES (%(工单流水号)s, %(投诉内容)s, %(处理结果)s, %(我方办结原因)s, %(区县)s, %(乡镇)s, %(关联自然村_小区名)s, %(经度)s, %(纬度)s, %(关联基站代码)s, %(关联基站名称)s, %(投诉大类)s, %(投诉原因)s, %(网络类型)s, %(区域)s, %(区域细类)s, %(解决措施)s, %(解决措施_详)s)]
[parameters: {'工单流水号': 'TZ0000202007027856626', '投诉内容': '是否实名认证:是\r\n是否违章停机:否\r\n是否有在途单:该用户无在途单\r\n计费状态:正常\r\nHSS平台-是否降速:否\r\n数据业务是否正常:是\r\n是否有流量超出:否\r\n是否为流量封顶断网:否\r\n是否降速查询:否\r\n用户是否处于群障区域:否\r\n国漫语音和国漫网络功 ... (57 characters truncated) ... \r\n语音，上网数据业务比对:正常\r\n故障地址： 曲靖市麒麟区益宁街道牛街社区龙骨村\r\n问题描述(故障时间\\是否有信号\\用户状态等)：用户反映本机显示 4G网络信号，但是信号不稳定，使用网速慢且会掉线，对此不满\r\n用户要求：核实处理\r\n呼入号码：IM号:18182996065', '处理结果': '投诉产生原因：用户终端问题\r\n经过核实，用户投诉地点龙骨村，属自然村_场景，用户接收是我方麒麟沿江牛街龙骨村基站信号，用户距离我方基站只有500米，该基站无故障，从我方掌握的基站信息结合用户的地理位置可以判断当地覆盖正常，所以无需进行现场测试，可以判断当地4G网络信号覆盖正常，通过后台观察用户投诉时段7月2,22:00，基站在线用户数14人，平均上网速度6Mbps，可以判断当地其他用户使用正常；用户无法正常使用并非我方网络故障导致，属于用户手机终端原因导致使用不正常.建议用户重启手机再试或带手机到当地营业网点检查手机和卡。\r\n', '我方办结原因': '用户终端故障', '区县': '麒麟', '乡镇': '沿江', '关联自然村_小区名': '龙骨村', '经度': ' 103.829341', '纬度': '25.475900', '关联基站代码': '', '关联基站名称': '', '投诉大类': None, '投诉原因': None, '网络类型': None, '区域': '农村', '区域细类': '自然村', '解决措施': '用户自行处理', '解决措施_详': None}]
(Background on this error at: http://sqlalche.me/e/13/9h9h)
[2020-07-03 15:50:05 +0800] [2754] [INFO] Handling signal: term
[2020-07-03 15:50:05 +0800] [2758] [INFO] Worker exiting (pid: 2758)
/home/fms/project/venv/lib/python3.7/site-packages/pymysql/cursors.py:170: Warning: (1366, "Incorrect string value: '\\xD6\\xD0\\xB9\\xFA\\xB1\\xEA...' for column 'VARIABLE_VALUE' at row 480")
  result = self._query(query)
[2020-07-03 15:50:05 +0800] [2762] [INFO] Worker exiting (pid: 2762)
[2020-07-03 15:50:05 +0800] [2763] [INFO] Worker exiting (pid: 2763)
[2020-07-03 15:50:05 +0800] [2765] [INFO] Worker exiting (pid: 2765)
[2020-07-03 15:50:10 +0800] [2754] [INFO] Shutting down: Master
[2020-07-03 15:59:57 +0800] [2833] [INFO] Starting gunicorn 20.0.4
[2020-07-03 15:59:57 +0800] [2833] [INFO] Listening at: http://0.0.0.0:8002 (2833)
[2020-07-03 15:59:57 +0800] [2833] [INFO] Using worker: sync
[2020-07-03 15:59:57 +0800] [2836] [INFO] Booting worker with pid: 2836
[2020-07-03 15:59:57 +0800] [2837] [INFO] Booting worker with pid: 2837
[2020-07-03 15:59:57 +0800] [2838] [INFO] Booting worker with pid: 2838
[2020-07-03 15:59:57 +0800] [2839] [INFO] Booting worker with pid: 2839
[2020-07-03 16:00:43 +0800] [2833] [INFO] Handling signal: term
[2020-07-03 16:00:43 +0800] [2837] [INFO] Worker exiting (pid: 2837)
[2020-07-03 16:00:43 +0800] [2836] [INFO] Worker exiting (pid: 2836)
[2020-07-03 16:00:43 +0800] [2838] [INFO] Worker exiting (pid: 2838)
[2020-07-03 16:00:43 +0800] [2839] [INFO] Worker exiting (pid: 2839)
[2020-07-03 16:00:43 +0800] [2833] [INFO] Shutting down: Master
[2020-07-03 16:00:45 +0800] [2877] [INFO] Starting gunicorn 20.0.4
[2020-07-03 16:00:45 +0800] [2877] [INFO] Listening at: http://0.0.0.0:8002 (2877)
[2020-07-03 16:00:45 +0800] [2877] [INFO] Using worker: sync
[2020-07-03 16:00:45 +0800] [2883] [INFO] Booting worker with pid: 2883
[2020-07-03 16:00:45 +0800] [2884] [INFO] Booting worker with pid: 2884
[2020-07-03 16:00:45 +0800] [2886] [INFO] Booting worker with pid: 2886
[2020-07-03 16:00:45 +0800] [2889] [INFO] Booting worker with pid: 2889
[2020-07-03 16:10:45 +0800] [2877] [INFO] Handling signal: term
[2020-07-03 16:10:45 +0800] [2883] [INFO] Worker exiting (pid: 2883)
[2020-07-03 16:10:45 +0800] [2886] [INFO] Worker exiting (pid: 2886)
[2020-07-03 16:10:45 +0800] [2889] [INFO] Worker exiting (pid: 2889)
[2020-07-03 16:10:45 +0800] [2884] [INFO] Worker exiting (pid: 2884)
[2020-07-03 16:10:47 +0800] [2877] [INFO] Shutting down: Master
[2020-07-03 16:10:49 +0800] [2930] [INFO] Starting gunicorn 20.0.4
[2020-07-03 16:10:49 +0800] [2930] [INFO] Listening at: http://0.0.0.0:8002 (2930)
[2020-07-03 16:10:49 +0800] [2930] [INFO] Using worker: sync
[2020-07-03 16:10:49 +0800] [2937] [INFO] Booting worker with pid: 2937
[2020-07-03 16:10:49 +0800] [2939] [INFO] Booting worker with pid: 2939
[2020-07-03 16:10:49 +0800] [2940] [INFO] Booting worker with pid: 2940
[2020-07-03 16:10:49 +0800] [2942] [INFO] Booting worker with pid: 2942
/home/fms/project/venv/lib/python3.7/site-packages/pymysql/cursors.py:170: Warning: (1366, "Incorrect string value: '\\xD6\\xD0\\xB9\\xFA\\xB1\\xEA...' for column 'VARIABLE_VALUE' at row 480")
  result = self._query(query)
[2020-07-03 16:56:58,603] ERROR in app: Exception on /put [POST]
Traceback (most recent call last):
  File "/home/fms/project/venv/lib/python3.7/site-packages/sqlalchemy/engine/base.py", line 1278, in _execute_context
    cursor, statement, parameters, context
  File "/home/fms/project/venv/lib/python3.7/site-packages/sqlalchemy/engine/default.py", line 593, in do_execute
    cursor.execute(statement, parameters)
  File "/home/fms/project/venv/lib/python3.7/site-packages/pymysql/cursors.py", line 170, in execute
    result = self._query(query)
  File "/home/fms/project/venv/lib/python3.7/site-packages/pymysql/cursors.py", line 328, in _query
    conn.query(q)
  File "/home/fms/project/venv/lib/python3.7/site-packages/pymysql/connections.py", line 517, in query
    self._affected_rows = self._read_query_result(unbuffered=unbuffered)
  File "/home/fms/project/venv/lib/python3.7/site-packages/pymysql/connections.py", line 732, in _read_query_result
    result.read()
  File "/home/fms/project/venv/lib/python3.7/site-packages/pymysql/connections.py", line 1075, in read
    first_packet = self.connection._read_packet()
  File "/home/fms/project/venv/lib/python3.7/site-packages/pymysql/connections.py", line 684, in _read_packet
    packet.check_error()
  File "/home/fms/project/venv/lib/python3.7/site-packages/pymysql/protocol.py", line 220, in check_error
    err.raise_mysql_exception(self._data)
  File "/home/fms/project/venv/lib/python3.7/site-packages/pymysql/err.py", line 109, in raise_mysql_exception
    raise errorclass(errno, errval)
pymysql.err.DataError: (1406, "Data too long for column '经度' at row 1")

The above exception was the direct cause of the following exception:

Traceback (most recent call last):
  File "/home/fms/project/venv/lib/python3.7/site-packages/flask/app.py", line 2447, in wsgi_app
    response = self.full_dispatch_request()
  File "/home/fms/project/venv/lib/python3.7/site-packages/flask/app.py", line 1952, in full_dispatch_request
    rv = self.handle_user_exception(e)
  File "/home/fms/project/venv/lib/python3.7/site-packages/flask/app.py", line 1821, in handle_user_exception
    reraise(exc_type, exc_value, tb)
  File "/home/fms/project/venv/lib/python3.7/site-packages/flask/_compat.py", line 39, in reraise
    raise value
  File "/home/fms/project/venv/lib/python3.7/site-packages/flask/app.py", line 1950, in full_dispatch_request
    rv = self.dispatch_request()
  File "/home/fms/project/venv/lib/python3.7/site-packages/flask/app.py", line 1936, in dispatch_request
    return self.view_functions[rule.endpoint](**req.view_args)
  File "/home/fms/project/work2database/app.py", line 108, in put2datebase
    put2base(complaint_info, session_tousu)
  File "/home/fms/project/work2database/func.py", line 65, in put2base
    session3.commit()
  File "/home/fms/project/venv/lib/python3.7/site-packages/sqlalchemy/orm/session.py", line 1042, in commit
    self.transaction.commit()
  File "/home/fms/project/venv/lib/python3.7/site-packages/sqlalchemy/orm/session.py", line 504, in commit
    self._prepare_impl()
  File "/home/fms/project/venv/lib/python3.7/site-packages/sqlalchemy/orm/session.py", line 483, in _prepare_impl
    self.session.flush()
  File "/home/fms/project/venv/lib/python3.7/site-packages/sqlalchemy/orm/session.py", line 2523, in flush
    self._flush(objects)
  File "/home/fms/project/venv/lib/python3.7/site-packages/sqlalchemy/orm/session.py", line 2664, in _flush
    transaction.rollback(_capture_exception=True)
  File "/home/fms/project/venv/lib/python3.7/site-packages/sqlalchemy/util/langhelpers.py", line 69, in __exit__
    exc_value, with_traceback=exc_tb,
  File "/home/fms/project/venv/lib/python3.7/site-packages/sqlalchemy/util/compat.py", line 178, in raise_
    raise exception
  File "/home/fms/project/venv/lib/python3.7/site-packages/sqlalchemy/orm/session.py", line 2624, in _flush
    flush_context.execute()
  File "/home/fms/project/venv/lib/python3.7/site-packages/sqlalchemy/orm/unitofwork.py", line 422, in execute
    rec.execute(self)
  File "/home/fms/project/venv/lib/python3.7/site-packages/sqlalchemy/orm/unitofwork.py", line 589, in execute
    uow,
  File "/home/fms/project/venv/lib/python3.7/site-packages/sqlalchemy/orm/persistence.py", line 245, in save_obj
    insert,
  File "/home/fms/project/venv/lib/python3.7/site-packages/sqlalchemy/orm/persistence.py", line 1083, in _emit_insert_statements
    c = cached_connections[connection].execute(statement, multiparams)
  File "/home/fms/project/venv/lib/python3.7/site-packages/sqlalchemy/engine/base.py", line 1014, in execute
    return meth(self, multiparams, params)
  File "/home/fms/project/venv/lib/python3.7/site-packages/sqlalchemy/sql/elements.py", line 298, in _execute_on_connection
    return connection._execute_clauseelement(self, multiparams, params)
  File "/home/fms/project/venv/lib/python3.7/site-packages/sqlalchemy/engine/base.py", line 1133, in _execute_clauseelement
    distilled_params,
  File "/home/fms/project/venv/lib/python3.7/site-packages/sqlalchemy/engine/base.py", line 1318, in _execute_context
    e, statement, parameters, cursor, context
  File "/home/fms/project/venv/lib/python3.7/site-packages/sqlalchemy/engine/base.py", line 1512, in _handle_dbapi_exception
    sqlalchemy_exception, with_traceback=exc_info[2], from_=e
  File "/home/fms/project/venv/lib/python3.7/site-packages/sqlalchemy/util/compat.py", line 178, in raise_
    raise exception
  File "/home/fms/project/venv/lib/python3.7/site-packages/sqlalchemy/engine/base.py", line 1278, in _execute_context
    cursor, statement, parameters, context
  File "/home/fms/project/venv/lib/python3.7/site-packages/sqlalchemy/engine/default.py", line 593, in do_execute
    cursor.execute(statement, parameters)
  File "/home/fms/project/venv/lib/python3.7/site-packages/pymysql/cursors.py", line 170, in execute
    result = self._query(query)
  File "/home/fms/project/venv/lib/python3.7/site-packages/pymysql/cursors.py", line 328, in _query
    conn.query(q)
  File "/home/fms/project/venv/lib/python3.7/site-packages/pymysql/connections.py", line 517, in query
    self._affected_rows = self._read_query_result(unbuffered=unbuffered)
  File "/home/fms/project/venv/lib/python3.7/site-packages/pymysql/connections.py", line 732, in _read_query_result
    result.read()
  File "/home/fms/project/venv/lib/python3.7/site-packages/pymysql/connections.py", line 1075, in read
    first_packet = self.connection._read_packet()
  File "/home/fms/project/venv/lib/python3.7/site-packages/pymysql/connections.py", line 684, in _read_packet
    packet.check_error()
  File "/home/fms/project/venv/lib/python3.7/site-packages/pymysql/protocol.py", line 220, in check_error
    err.raise_mysql_exception(self._data)
  File "/home/fms/project/venv/lib/python3.7/site-packages/pymysql/err.py", line 109, in raise_mysql_exception
    raise errorclass(errno, errval)
sqlalchemy.exc.DataError: (pymysql.err.DataError) (1406, "Data too long for column '经度' at row 1")
[SQL: INSERT INTO tousu (`工单流水号`, `投诉内容`, `处理结果`, `我方办结原因`, `区县`, `乡镇`, `关联自然村_小区名`, `经度`, `纬度`, `关联基站代码`, `关联基站名称`, `投诉大类`, `投诉原因`, `网络类型`, `区域`, `区域细类`, `解决措施`, `解决措施_详`) VALUES (%(工单流水号)s, %(投诉内容)s, %(处理结果)s, %(我方办结原因)s, %(区县)s, %(乡镇)s, %(关联自然村_小区名)s, %(经度)s, %(纬度)s, %(关联基站代码)s, %(关联基站名称)s, %(投诉大类)s, %(投诉原因)s, %(网络类型)s, %(区域)s, %(区域细类)s, %(解决措施)s, %(解决措施_详)s)]
[parameters: {'工单流水号': 'TZ0000202007027856787', '投诉内容': '是否实名认证:是\r\n是否违章停机:否\r\n是否有在途单:该用户无在途单\r\n计费状态:正常\r\nHSS平台-是否降速:否\r\n数据业务是否正常:是\r\n是否有流量超出:否\r\n是否为流量封顶断网:否\r\n是否降速查询:否\r\n用户是否处于群障区域:否\r\n国漫语音和国漫网络功 ... (20 characters truncated) ... 匹配:否\r\n用户拦截状态是否正常:是\r\nCRM用户状态是否正常:是\r\n语音，上网数据业务比对:正常\r\n故障地址：曲靖市会泽县驾车乡光头村大窝坡小组\r\n问题描述(故障时间\\是否有信号\\用户状态等)：4G信号弱，上网网速慢，用户上网方式：4G\r\n用户要求：\r\n呼入号码：', '处理结果': '投诉产生原因：用户终端问题\r\n经过核实，用户投诉地点大窝坡，属自然村场景，用户接收是我方会泽驾车乡光头村委会大窝坡基站信号，用户距离我方基站只有615米（详见附件地图），该基站无故障，从我方掌握的基站信息结合用户的地理位置可以判断当地覆盖正常，所以无需进行现场测试，可以判断当地4G网络信号覆盖正常，通过后台观察用户投诉时段7月2,20:00，基站在线用户数47人，平均上网速度2Mbps，可以判断当地其他用户使用正常；因我方农村基站带宽比较小，用户上网用来看视频，打开网页等会受一定影响，所以我方建议用户在家里面使用有线宽带。', '我方办结原因': '用户终端故障', '区县': '会泽', '乡镇': '', '关联自然村_小区名': '大窝坡', '经度': ' 103.459411', '纬度': '26.022658', '关联基站代码': '', '关联基站名称': '', '投诉大类': None, '投诉原因': None, '网络类型': None, '区域': '农村', '区域细类': '自然村', '解决措施': '使用WIFI替代', '解决措施_详': None}]
(Background on this error at: http://sqlalche.me/e/13/9h9h)
[2020-07-03 16:57:10 +0800] [2930] [INFO] Handling signal: term
/home/fms/project/venv/lib/python3.7/site-packages/pymysql/cursors.py:170: Warning: (1366, "Incorrect string value: '\\xD6\\xD0\\xB9\\xFA\\xB1\\xEA...' for column 'VARIABLE_VALUE' at row 480")
  result = self._query(query)
[2020-07-03 16:57:10 +0800] [2937] [INFO] Worker exiting (pid: 2937)
[2020-07-03 16:57:10 +0800] [2940] [INFO] Worker exiting (pid: 2940)
[2020-07-03 16:57:10 +0800] [2942] [INFO] Worker exiting (pid: 2942)
/home/fms/project/venv/lib/python3.7/site-packages/pymysql/cursors.py:170: Warning: (1366, "Incorrect string value: '\\xD6\\xD0\\xB9\\xFA\\xB1\\xEA...' for column 'VARIABLE_VALUE' at row 480")
  result = self._query(query)
[2020-07-03 16:57:10 +0800] [2939] [INFO] Worker exiting (pid: 2939)
[2020-07-03 16:57:26 +0800] [2962] [INFO] Starting gunicorn 20.0.4
[2020-07-03 16:57:26 +0800] [2962] [INFO] Listening at: http://0.0.0.0:8002 (2962)
[2020-07-03 16:57:26 +0800] [2962] [INFO] Using worker: sync
[2020-07-03 16:57:26 +0800] [2967] [INFO] Booting worker with pid: 2967
[2020-07-03 16:57:26 +0800] [2970] [INFO] Booting worker with pid: 2970
[2020-07-03 16:57:27 +0800] [2971] [INFO] Booting worker with pid: 2971
[2020-07-03 16:57:27 +0800] [2973] [INFO] Booting worker with pid: 2973
/home/fms/project/venv/lib/python3.7/site-packages/pymysql/cursors.py:170: Warning: (1366, "Incorrect string value: '\\xD6\\xD0\\xB9\\xFA\\xB1\\xEA...' for column 'VARIABLE_VALUE' at row 480")
  result = self._query(query)
[2020-07-03 16:58:32,462] ERROR in app: Exception on /put [POST]
Traceback (most recent call last):
  File "/home/fms/project/venv/lib/python3.7/site-packages/sqlalchemy/engine/base.py", line 1278, in _execute_context
    cursor, statement, parameters, context
  File "/home/fms/project/venv/lib/python3.7/site-packages/sqlalchemy/engine/default.py", line 593, in do_execute
    cursor.execute(statement, parameters)
  File "/home/fms/project/venv/lib/python3.7/site-packages/pymysql/cursors.py", line 170, in execute
    result = self._query(query)
  File "/home/fms/project/venv/lib/python3.7/site-packages/pymysql/cursors.py", line 328, in _query
    conn.query(q)
  File "/home/fms/project/venv/lib/python3.7/site-packages/pymysql/connections.py", line 517, in query
    self._affected_rows = self._read_query_result(unbuffered=unbuffered)
  File "/home/fms/project/venv/lib/python3.7/site-packages/pymysql/connections.py", line 732, in _read_query_result
    result.read()
  File "/home/fms/project/venv/lib/python3.7/site-packages/pymysql/connections.py", line 1075, in read
    first_packet = self.connection._read_packet()
  File "/home/fms/project/venv/lib/python3.7/site-packages/pymysql/connections.py", line 684, in _read_packet
    packet.check_error()
  File "/home/fms/project/venv/lib/python3.7/site-packages/pymysql/protocol.py", line 220, in check_error
    err.raise_mysql_exception(self._data)
  File "/home/fms/project/venv/lib/python3.7/site-packages/pymysql/err.py", line 109, in raise_mysql_exception
    raise errorclass(errno, errval)
pymysql.err.DataError: (1406, "Data too long for column '经度' at row 1")

The above exception was the direct cause of the following exception:

Traceback (most recent call last):
  File "/home/fms/project/venv/lib/python3.7/site-packages/flask/app.py", line 2447, in wsgi_app
    response = self.full_dispatch_request()
  File "/home/fms/project/venv/lib/python3.7/site-packages/flask/app.py", line 1952, in full_dispatch_request
    rv = self.handle_user_exception(e)
  File "/home/fms/project/venv/lib/python3.7/site-packages/flask/app.py", line 1821, in handle_user_exception
    reraise(exc_type, exc_value, tb)
  File "/home/fms/project/venv/lib/python3.7/site-packages/flask/_compat.py", line 39, in reraise
    raise value
  File "/home/fms/project/venv/lib/python3.7/site-packages/flask/app.py", line 1950, in full_dispatch_request
    rv = self.dispatch_request()
  File "/home/fms/project/venv/lib/python3.7/site-packages/flask/app.py", line 1936, in dispatch_request
    return self.view_functions[rule.endpoint](**req.view_args)
  File "/home/fms/project/work2database/app.py", line 108, in put2datebase
    put2base(complaint_info, session_tousu)
  File "/home/fms/project/work2database/func.py", line 65, in put2base
    session3.commit()
  File "/home/fms/project/venv/lib/python3.7/site-packages/sqlalchemy/orm/session.py", line 1042, in commit
    self.transaction.commit()
  File "/home/fms/project/venv/lib/python3.7/site-packages/sqlalchemy/orm/session.py", line 504, in commit
    self._prepare_impl()
  File "/home/fms/project/venv/lib/python3.7/site-packages/sqlalchemy/orm/session.py", line 483, in _prepare_impl
    self.session.flush()
  File "/home/fms/project/venv/lib/python3.7/site-packages/sqlalchemy/orm/session.py", line 2523, in flush
    self._flush(objects)
  File "/home/fms/project/venv/lib/python3.7/site-packages/sqlalchemy/orm/session.py", line 2664, in _flush
    transaction.rollback(_capture_exception=True)
  File "/home/fms/project/venv/lib/python3.7/site-packages/sqlalchemy/util/langhelpers.py", line 69, in __exit__
    exc_value, with_traceback=exc_tb,
  File "/home/fms/project/venv/lib/python3.7/site-packages/sqlalchemy/util/compat.py", line 178, in raise_
    raise exception
  File "/home/fms/project/venv/lib/python3.7/site-packages/sqlalchemy/orm/session.py", line 2624, in _flush
    flush_context.execute()
  File "/home/fms/project/venv/lib/python3.7/site-packages/sqlalchemy/orm/unitofwork.py", line 422, in execute
    rec.execute(self)
  File "/home/fms/project/venv/lib/python3.7/site-packages/sqlalchemy/orm/unitofwork.py", line 589, in execute
    uow,
  File "/home/fms/project/venv/lib/python3.7/site-packages/sqlalchemy/orm/persistence.py", line 245, in save_obj
    insert,
  File "/home/fms/project/venv/lib/python3.7/site-packages/sqlalchemy/orm/persistence.py", line 1083, in _emit_insert_statements
    c = cached_connections[connection].execute(statement, multiparams)
  File "/home/fms/project/venv/lib/python3.7/site-packages/sqlalchemy/engine/base.py", line 1014, in execute
    return meth(self, multiparams, params)
  File "/home/fms/project/venv/lib/python3.7/site-packages/sqlalchemy/sql/elements.py", line 298, in _execute_on_connection
    return connection._execute_clauseelement(self, multiparams, params)
  File "/home/fms/project/venv/lib/python3.7/site-packages/sqlalchemy/engine/base.py", line 1133, in _execute_clauseelement
    distilled_params,
  File "/home/fms/project/venv/lib/python3.7/site-packages/sqlalchemy/engine/base.py", line 1318, in _execute_context
    e, statement, parameters, cursor, context
  File "/home/fms/project/venv/lib/python3.7/site-packages/sqlalchemy/engine/base.py", line 1512, in _handle_dbapi_exception
    sqlalchemy_exception, with_traceback=exc_info[2], from_=e
  File "/home/fms/project/venv/lib/python3.7/site-packages/sqlalchemy/util/compat.py", line 178, in raise_
    raise exception
  File "/home/fms/project/venv/lib/python3.7/site-packages/sqlalchemy/engine/base.py", line 1278, in _execute_context
    cursor, statement, parameters, context
  File "/home/fms/project/venv/lib/python3.7/site-packages/sqlalchemy/engine/default.py", line 593, in do_execute
    cursor.execute(statement, parameters)
  File "/home/fms/project/venv/lib/python3.7/site-packages/pymysql/cursors.py", line 170, in execute
    result = self._query(query)
  File "/home/fms/project/venv/lib/python3.7/site-packages/pymysql/cursors.py", line 328, in _query
    conn.query(q)
  File "/home/fms/project/venv/lib/python3.7/site-packages/pymysql/connections.py", line 517, in query
    self._affected_rows = self._read_query_result(unbuffered=unbuffered)
  File "/home/fms/project/venv/lib/python3.7/site-packages/pymysql/connections.py", line 732, in _read_query_result
    result.read()
  File "/home/fms/project/venv/lib/python3.7/site-packages/pymysql/connections.py", line 1075, in read
    first_packet = self.connection._read_packet()
  File "/home/fms/project/venv/lib/python3.7/site-packages/pymysql/connections.py", line 684, in _read_packet
    packet.check_error()
  File "/home/fms/project/venv/lib/python3.7/site-packages/pymysql/protocol.py", line 220, in check_error
    err.raise_mysql_exception(self._data)
  File "/home/fms/project/venv/lib/python3.7/site-packages/pymysql/err.py", line 109, in raise_mysql_exception
    raise errorclass(errno, errval)
sqlalchemy.exc.DataError: (pymysql.err.DataError) (1406, "Data too long for column '经度' at row 1")
[SQL: INSERT INTO tousu (`工单流水号`, `投诉内容`, `处理结果`, `我方办结原因`, `区县`, `乡镇`, `关联自然村_小区名`, `经度`, `纬度`, `关联基站代码`, `关联基站名称`, `投诉大类`, `投诉原因`, `网络类型`, `区域`, `区域细类`, `解决措施`, `解决措施_详`) VALUES (%(工单流水号)s, %(投诉内容)s, %(处理结果)s, %(我方办结原因)s, %(区县)s, %(乡镇)s, %(关联自然村_小区名)s, %(经度)s, %(纬度)s, %(关联基站代码)s, %(关联基站名称)s, %(投诉大类)s, %(投诉原因)s, %(网络类型)s, %(区域)s, %(区域细类)s, %(解决措施)s, %(解决措施_详)s)]
[parameters: {'工单流水号': 'TZ0000202007027856787', '投诉内容': '是否实名认证:是\r\n是否违章停机:否\r\n是否有在途单:该用户无在途单\r\n计费状态:正常\r\nHSS平台-是否降速:否\r\n数据业务是否正常:是\r\n是否有流量超出:否\r\n是否为流量封顶断网:否\r\n是否降速查询:否\r\n用户是否处于群障区域:否\r\n国漫语音和国漫网络功 ... (20 characters truncated) ... 匹配:否\r\n用户拦截状态是否正常:是\r\nCRM用户状态是否正常:是\r\n语音，上网数据业务比对:正常\r\n故障地址：曲靖市会泽县驾车乡光头村大窝坡小组\r\n问题描述(故障时间\\是否有信号\\用户状态等)：4G信号弱，上网网速慢，用户上网方式：4G\r\n用户要求：\r\n呼入号码：', '处理结果': '投诉产生原因：用户终端问题\r\n经过核实，用户投诉地点大窝坡，属自然村场景，用户接收是我方会泽驾车乡光头村委会大窝坡基站信号，用户距离我方基站只有615米（详见附件地图），该基站无故障，从我方掌握的基站信息结合用户的地理位置可以判断当地覆盖正常，所以无需进行现场测试，可以判断当地4G网络信号覆盖正常，通过后台观察用户投诉时段7月2,20:00，基站在线用户数47人，平均上网速度2Mbps，可以判断当地其他用户使用正常；因我方农村基站带宽比较小，用户上网用来看视频，打开网页等会受一定影响，所以我方建议用户在家里面使用有线宽带。', '我方办结原因': '用户终端故障', '区县': '会泽', '乡镇': '', '关联自然村_小区名': '大窝坡', '经度': ' 103.459411', '纬度': '26.022658', '关联基站代码': '', '关联基站名称': '', '投诉大类': None, '投诉原因': None, '网络类型': None, '区域': '农村', '区域细类': '自然村', '解决措施': '使用WIFI替代', '解决措施_详': None}]
(Background on this error at: http://sqlalche.me/e/13/9h9h)
[2020-07-03 16:58:51 +0800] [2962] [INFO] Handling signal: term
[2020-07-03 16:58:51 +0800] [2967] [INFO] Worker exiting (pid: 2967)
[2020-07-03 16:58:51 +0800] [2971] [INFO] Worker exiting (pid: 2971)
[2020-07-03 16:58:51 +0800] [2970] [INFO] Worker exiting (pid: 2970)
[2020-07-03 16:58:51 +0800] [2973] [INFO] Worker exiting (pid: 2973)
[2020-07-03 16:58:51 +0800] [2962] [INFO] Shutting down: Master
[2020-07-03 16:58:54 +0800] [2977] [INFO] Starting gunicorn 20.0.4
[2020-07-03 16:58:54 +0800] [2977] [INFO] Listening at: http://0.0.0.0:8002 (2977)
[2020-07-03 16:58:54 +0800] [2977] [INFO] Using worker: sync
[2020-07-03 16:58:54 +0800] [2983] [INFO] Booting worker with pid: 2983
[2020-07-03 16:58:54 +0800] [2984] [INFO] Booting worker with pid: 2984
[2020-07-03 16:58:54 +0800] [2986] [INFO] Booting worker with pid: 2986
[2020-07-03 16:58:54 +0800] [2987] [INFO] Booting worker with pid: 2987
/home/fms/project/venv/lib/python3.7/site-packages/pymysql/cursors.py:170: Warning: (1366, "Incorrect string value: '\\xD6\\xD0\\xB9\\xFA\\xB1\\xEA...' for column 'VARIABLE_VALUE' at row 480")
  result = self._query(query)
[2020-07-03 17:30:59,213] ERROR in app: Exception on /put [POST]
Traceback (most recent call last):
  File "/home/fms/project/venv/lib/python3.7/site-packages/sqlalchemy/engine/base.py", line 1278, in _execute_context
    cursor, statement, parameters, context
  File "/home/fms/project/venv/lib/python3.7/site-packages/sqlalchemy/engine/default.py", line 593, in do_execute
    cursor.execute(statement, parameters)
  File "/home/fms/project/venv/lib/python3.7/site-packages/pymysql/cursors.py", line 170, in execute
    result = self._query(query)
  File "/home/fms/project/venv/lib/python3.7/site-packages/pymysql/cursors.py", line 328, in _query
    conn.query(q)
  File "/home/fms/project/venv/lib/python3.7/site-packages/pymysql/connections.py", line 517, in query
    self._affected_rows = self._read_query_result(unbuffered=unbuffered)
  File "/home/fms/project/venv/lib/python3.7/site-packages/pymysql/connections.py", line 732, in _read_query_result
    result.read()
  File "/home/fms/project/venv/lib/python3.7/site-packages/pymysql/connections.py", line 1075, in read
    first_packet = self.connection._read_packet()
  File "/home/fms/project/venv/lib/python3.7/site-packages/pymysql/connections.py", line 684, in _read_packet
    packet.check_error()
  File "/home/fms/project/venv/lib/python3.7/site-packages/pymysql/protocol.py", line 220, in check_error
    err.raise_mysql_exception(self._data)
  File "/home/fms/project/venv/lib/python3.7/site-packages/pymysql/err.py", line 109, in raise_mysql_exception
    raise errorclass(errno, errval)
pymysql.err.DataError: (1406, "Data too long for column '经度' at row 1")

The above exception was the direct cause of the following exception:

Traceback (most recent call last):
  File "/home/fms/project/venv/lib/python3.7/site-packages/flask/app.py", line 2447, in wsgi_app
    response = self.full_dispatch_request()
  File "/home/fms/project/venv/lib/python3.7/site-packages/flask/app.py", line 1952, in full_dispatch_request
    rv = self.handle_user_exception(e)
  File "/home/fms/project/venv/lib/python3.7/site-packages/flask/app.py", line 1821, in handle_user_exception
    reraise(exc_type, exc_value, tb)
  File "/home/fms/project/venv/lib/python3.7/site-packages/flask/_compat.py", line 39, in reraise
    raise value
  File "/home/fms/project/venv/lib/python3.7/site-packages/flask/app.py", line 1950, in full_dispatch_request
    rv = self.dispatch_request()
  File "/home/fms/project/venv/lib/python3.7/site-packages/flask/app.py", line 1936, in dispatch_request
    return self.view_functions[rule.endpoint](**req.view_args)
  File "/home/fms/project/work2database/app.py", line 108, in put2datebase
    put2base(complaint_info, session_tousu)
  File "/home/fms/project/work2database/func.py", line 65, in put2base
    session3.commit()
  File "/home/fms/project/venv/lib/python3.7/site-packages/sqlalchemy/orm/session.py", line 1042, in commit
    self.transaction.commit()
  File "/home/fms/project/venv/lib/python3.7/site-packages/sqlalchemy/orm/session.py", line 504, in commit
    self._prepare_impl()
  File "/home/fms/project/venv/lib/python3.7/site-packages/sqlalchemy/orm/session.py", line 483, in _prepare_impl
    self.session.flush()
  File "/home/fms/project/venv/lib/python3.7/site-packages/sqlalchemy/orm/session.py", line 2523, in flush
    self._flush(objects)
  File "/home/fms/project/venv/lib/python3.7/site-packages/sqlalchemy/orm/session.py", line 2664, in _flush
    transaction.rollback(_capture_exception=True)
  File "/home/fms/project/venv/lib/python3.7/site-packages/sqlalchemy/util/langhelpers.py", line 69, in __exit__
    exc_value, with_traceback=exc_tb,
  File "/home/fms/project/venv/lib/python3.7/site-packages/sqlalchemy/util/compat.py", line 178, in raise_
    raise exception
  File "/home/fms/project/venv/lib/python3.7/site-packages/sqlalchemy/orm/session.py", line 2624, in _flush
    flush_context.execute()
  File "/home/fms/project/venv/lib/python3.7/site-packages/sqlalchemy/orm/unitofwork.py", line 422, in execute
    rec.execute(self)
  File "/home/fms/project/venv/lib/python3.7/site-packages/sqlalchemy/orm/unitofwork.py", line 589, in execute
    uow,
  File "/home/fms/project/venv/lib/python3.7/site-packages/sqlalchemy/orm/persistence.py", line 245, in save_obj
    insert,
  File "/home/fms/project/venv/lib/python3.7/site-packages/sqlalchemy/orm/persistence.py", line 1083, in _emit_insert_statements
    c = cached_connections[connection].execute(statement, multiparams)
  File "/home/fms/project/venv/lib/python3.7/site-packages/sqlalchemy/engine/base.py", line 1014, in execute
    return meth(self, multiparams, params)
  File "/home/fms/project/venv/lib/python3.7/site-packages/sqlalchemy/sql/elements.py", line 298, in _execute_on_connection
    return connection._execute_clauseelement(self, multiparams, params)
  File "/home/fms/project/venv/lib/python3.7/site-packages/sqlalchemy/engine/base.py", line 1133, in _execute_clauseelement
    distilled_params,
  File "/home/fms/project/venv/lib/python3.7/site-packages/sqlalchemy/engine/base.py", line 1318, in _execute_context
    e, statement, parameters, cursor, context
  File "/home/fms/project/venv/lib/python3.7/site-packages/sqlalchemy/engine/base.py", line 1512, in _handle_dbapi_exception
    sqlalchemy_exception, with_traceback=exc_info[2], from_=e
  File "/home/fms/project/venv/lib/python3.7/site-packages/sqlalchemy/util/compat.py", line 178, in raise_
    raise exception
  File "/home/fms/project/venv/lib/python3.7/site-packages/sqlalchemy/engine/base.py", line 1278, in _execute_context
    cursor, statement, parameters, context
  File "/home/fms/project/venv/lib/python3.7/site-packages/sqlalchemy/engine/default.py", line 593, in do_execute
    cursor.execute(statement, parameters)
  File "/home/fms/project/venv/lib/python3.7/site-packages/pymysql/cursors.py", line 170, in execute
    result = self._query(query)
  File "/home/fms/project/venv/lib/python3.7/site-packages/pymysql/cursors.py", line 328, in _query
    conn.query(q)
  File "/home/fms/project/venv/lib/python3.7/site-packages/pymysql/connections.py", line 517, in query
    self._affected_rows = self._read_query_result(unbuffered=unbuffered)
  File "/home/fms/project/venv/lib/python3.7/site-packages/pymysql/connections.py", line 732, in _read_query_result
    result.read()
  File "/home/fms/project/venv/lib/python3.7/site-packages/pymysql/connections.py", line 1075, in read
    first_packet = self.connection._read_packet()
  File "/home/fms/project/venv/lib/python3.7/site-packages/pymysql/connections.py", line 684, in _read_packet
    packet.check_error()
  File "/home/fms/project/venv/lib/python3.7/site-packages/pymysql/protocol.py", line 220, in check_error
    err.raise_mysql_exception(self._data)
  File "/home/fms/project/venv/lib/python3.7/site-packages/pymysql/err.py", line 109, in raise_mysql_exception
    raise errorclass(errno, errval)
sqlalchemy.exc.DataError: (pymysql.err.DataError) (1406, "Data too long for column '经度' at row 1")
[SQL: INSERT INTO tousu (`工单流水号`, `投诉内容`, `处理结果`, `我方办结原因`, `区县`, `乡镇`, `关联自然村_小区名`, `经度`, `纬度`, `关联基站代码`, `关联基站名称`, `投诉大类`, `投诉原因`, `网络类型`, `区域`, `区域细类`, `解决措施`, `解决措施_详`) VALUES (%(工单流水号)s, %(投诉内容)s, %(处理结果)s, %(我方办结原因)s, %(区县)s, %(乡镇)s, %(关联自然村_小区名)s, %(经度)s, %(纬度)s, %(关联基站代码)s, %(关联基站名称)s, %(投诉大类)s, %(投诉原因)s, %(网络类型)s, %(区域)s, %(区域细类)s, %(解决措施)s, %(解决措施_详)s)]
[parameters: {'工单流水号': 'TZ0000202007037857096', '投诉内容': '是否违章停机:否\r\n是否有在途单:该用户无在途单\r\n计费状态:正常\r\nHSS平台-是否降速:否\r\n数据业务是否正常:是\r\n是否有流量超出:否\r\n是否为流量封顶断网:否\r\n是否降速查询:否\r\n用户是否处于群障区域:否\r\n国漫语音和国漫网络功能:否\r\n用户手机终 ... (13 characters truncated) ... r\n用户拦截状态是否正常:是\r\nCRM用户状态是否正常:是\r\n语音，上网数据业务比对:正常\r\n故障地址：云南省曲靖市富源县挑担夹马石村33号\r\n问题描述(故障时间\\是否有信号\\用户状态等)：手机没有4G信号，不能上网，要求尽快查询处理。\r\n呼入号码：19188753895', '处理结果': '投诉产生原因：用户终端问题\r\n经过核实，用户投诉地点夹马石村，属自然村场景，用户接收是我方富源县大河镇挑担夹马石村基站信号，用户距离我方基站只有133米（详见附件地图），该基站无故障，从我方掌握的基站信息结合用户的地理位置可以判断当地覆盖正常，所以无需进行现场测试，可以判断当地4G网络信号覆盖正常，通过后台观察用户投诉时段7月3,8:00，基站在线用户数10人，平均上网速度15Mbps，可以判断当地其他用户使用正常；用户无法正常使用并非我方网络故障导致，属于用户手机终端原因导致使用不正常.建议用户重启手机再试或带手机到当地营业网点检查手机和卡。', '我方办结原因': '用户终端故障', '区县': '富源', '乡镇': '大河', '关联自然村_小区名': '夹马石村', '经度': ' 104.426507', '纬度': '25.517152', '关联基站代码': '', '关联基站名称': '', '投诉大类': None, '投诉原因': None, '网络类型': None, '区域': '农村', '区域细类': '自然村', '解决措施': '用户自行处理', '解决措施_详': None}]
(Background on this error at: http://sqlalche.me/e/13/9h9h)
[2020-07-03 17:31:09 +0800] [2977] [INFO] Handling signal: term
[2020-07-03 17:31:09 +0800] [2984] [INFO] Worker exiting (pid: 2984)
[2020-07-03 17:31:09 +0800] [2983] [INFO] Worker exiting (pid: 2983)
/home/fms/project/venv/lib/python3.7/site-packages/pymysql/cursors.py:170: Warning: (1366, "Incorrect string value: '\\xD6\\xD0\\xB9\\xFA\\xB1\\xEA...' for column 'VARIABLE_VALUE' at row 480")
  result = self._query(query)
[2020-07-03 17:31:09 +0800] [2987] [INFO] Worker exiting (pid: 2987)
[2020-07-03 17:31:09 +0800] [2986] [INFO] Worker exiting (pid: 2986)
[2020-07-03 17:31:17 +0800] [2977] [INFO] Shutting down: Master
[2020-07-03 17:31:19 +0800] [3008] [INFO] Starting gunicorn 20.0.4
[2020-07-03 17:31:19 +0800] [3008] [INFO] Listening at: http://0.0.0.0:8002 (3008)
[2020-07-03 17:31:19 +0800] [3008] [INFO] Using worker: sync
[2020-07-03 17:31:19 +0800] [3015] [INFO] Booting worker with pid: 3015
[2020-07-03 17:31:19 +0800] [3016] [INFO] Booting worker with pid: 3016
[2020-07-03 17:31:19 +0800] [3018] [INFO] Booting worker with pid: 3018
[2020-07-03 17:31:19 +0800] [3020] [INFO] Booting worker with pid: 3020
/home/fms/project/venv/lib/python3.7/site-packages/pymysql/cursors.py:170: Warning: (1366, "Incorrect string value: '\\xD6\\xD0\\xB9\\xFA\\xB1\\xEA...' for column 'VARIABLE_VALUE' at row 480")
  result = self._query(query)
[2020-07-03 19:09:32,140] ERROR in app: Exception on /put [POST]
Traceback (most recent call last):
  File "/home/fms/project/venv/lib/python3.7/site-packages/sqlalchemy/engine/base.py", line 1278, in _execute_context
    cursor, statement, parameters, context
  File "/home/fms/project/venv/lib/python3.7/site-packages/sqlalchemy/engine/default.py", line 593, in do_execute
    cursor.execute(statement, parameters)
  File "/home/fms/project/venv/lib/python3.7/site-packages/pymysql/cursors.py", line 170, in execute
    result = self._query(query)
  File "/home/fms/project/venv/lib/python3.7/site-packages/pymysql/cursors.py", line 328, in _query
    conn.query(q)
  File "/home/fms/project/venv/lib/python3.7/site-packages/pymysql/connections.py", line 517, in query
    self._affected_rows = self._read_query_result(unbuffered=unbuffered)
  File "/home/fms/project/venv/lib/python3.7/site-packages/pymysql/connections.py", line 732, in _read_query_result
    result.read()
  File "/home/fms/project/venv/lib/python3.7/site-packages/pymysql/connections.py", line 1075, in read
    first_packet = self.connection._read_packet()
  File "/home/fms/project/venv/lib/python3.7/site-packages/pymysql/connections.py", line 684, in _read_packet
    packet.check_error()
  File "/home/fms/project/venv/lib/python3.7/site-packages/pymysql/protocol.py", line 220, in check_error
    err.raise_mysql_exception(self._data)
  File "/home/fms/project/venv/lib/python3.7/site-packages/pymysql/err.py", line 109, in raise_mysql_exception
    raise errorclass(errno, errval)
pymysql.err.DataError: (1406, "Data too long for column '经度' at row 1")

The above exception was the direct cause of the following exception:

Traceback (most recent call last):
  File "/home/fms/project/venv/lib/python3.7/site-packages/flask/app.py", line 2447, in wsgi_app
    response = self.full_dispatch_request()
  File "/home/fms/project/venv/lib/python3.7/site-packages/flask/app.py", line 1952, in full_dispatch_request
    rv = self.handle_user_exception(e)
  File "/home/fms/project/venv/lib/python3.7/site-packages/flask/app.py", line 1821, in handle_user_exception
    reraise(exc_type, exc_value, tb)
  File "/home/fms/project/venv/lib/python3.7/site-packages/flask/_compat.py", line 39, in reraise
    raise value
  File "/home/fms/project/venv/lib/python3.7/site-packages/flask/app.py", line 1950, in full_dispatch_request
    rv = self.dispatch_request()
  File "/home/fms/project/venv/lib/python3.7/site-packages/flask/app.py", line 1936, in dispatch_request
    return self.view_functions[rule.endpoint](**req.view_args)
  File "/home/fms/project/work2database/app.py", line 108, in put2datebase
    put2base(complaint_info, session_tousu)
  File "/home/fms/project/work2database/func.py", line 65, in put2base
    session3.commit()
  File "/home/fms/project/venv/lib/python3.7/site-packages/sqlalchemy/orm/session.py", line 1042, in commit
    self.transaction.commit()
  File "/home/fms/project/venv/lib/python3.7/site-packages/sqlalchemy/orm/session.py", line 504, in commit
    self._prepare_impl()
  File "/home/fms/project/venv/lib/python3.7/site-packages/sqlalchemy/orm/session.py", line 483, in _prepare_impl
    self.session.flush()
  File "/home/fms/project/venv/lib/python3.7/site-packages/sqlalchemy/orm/session.py", line 2523, in flush
    self._flush(objects)
  File "/home/fms/project/venv/lib/python3.7/site-packages/sqlalchemy/orm/session.py", line 2664, in _flush
    transaction.rollback(_capture_exception=True)
  File "/home/fms/project/venv/lib/python3.7/site-packages/sqlalchemy/util/langhelpers.py", line 69, in __exit__
    exc_value, with_traceback=exc_tb,
  File "/home/fms/project/venv/lib/python3.7/site-packages/sqlalchemy/util/compat.py", line 178, in raise_
    raise exception
  File "/home/fms/project/venv/lib/python3.7/site-packages/sqlalchemy/orm/session.py", line 2624, in _flush
    flush_context.execute()
  File "/home/fms/project/venv/lib/python3.7/site-packages/sqlalchemy/orm/unitofwork.py", line 422, in execute
    rec.execute(self)
  File "/home/fms/project/venv/lib/python3.7/site-packages/sqlalchemy/orm/unitofwork.py", line 589, in execute
    uow,
  File "/home/fms/project/venv/lib/python3.7/site-packages/sqlalchemy/orm/persistence.py", line 245, in save_obj
    insert,
  File "/home/fms/project/venv/lib/python3.7/site-packages/sqlalchemy/orm/persistence.py", line 1083, in _emit_insert_statements
    c = cached_connections[connection].execute(statement, multiparams)
  File "/home/fms/project/venv/lib/python3.7/site-packages/sqlalchemy/engine/base.py", line 1014, in execute
    return meth(self, multiparams, params)
  File "/home/fms/project/venv/lib/python3.7/site-packages/sqlalchemy/sql/elements.py", line 298, in _execute_on_connection
    return connection._execute_clauseelement(self, multiparams, params)
  File "/home/fms/project/venv/lib/python3.7/site-packages/sqlalchemy/engine/base.py", line 1133, in _execute_clauseelement
    distilled_params,
  File "/home/fms/project/venv/lib/python3.7/site-packages/sqlalchemy/engine/base.py", line 1318, in _execute_context
    e, statement, parameters, cursor, context
  File "/home/fms/project/venv/lib/python3.7/site-packages/sqlalchemy/engine/base.py", line 1512, in _handle_dbapi_exception
    sqlalchemy_exception, with_traceback=exc_info[2], from_=e
  File "/home/fms/project/venv/lib/python3.7/site-packages/sqlalchemy/util/compat.py", line 178, in raise_
    raise exception
  File "/home/fms/project/venv/lib/python3.7/site-packages/sqlalchemy/engine/base.py", line 1278, in _execute_context
    cursor, statement, parameters, context
  File "/home/fms/project/venv/lib/python3.7/site-packages/sqlalchemy/engine/default.py", line 593, in do_execute
    cursor.execute(statement, parameters)
  File "/home/fms/project/venv/lib/python3.7/site-packages/pymysql/cursors.py", line 170, in execute
    result = self._query(query)
  File "/home/fms/project/venv/lib/python3.7/site-packages/pymysql/cursors.py", line 328, in _query
    conn.query(q)
  File "/home/fms/project/venv/lib/python3.7/site-packages/pymysql/connections.py", line 517, in query
    self._affected_rows = self._read_query_result(unbuffered=unbuffered)
  File "/home/fms/project/venv/lib/python3.7/site-packages/pymysql/connections.py", line 732, in _read_query_result
    result.read()
  File "/home/fms/project/venv/lib/python3.7/site-packages/pymysql/connections.py", line 1075, in read
    first_packet = self.connection._read_packet()
  File "/home/fms/project/venv/lib/python3.7/site-packages/pymysql/connections.py", line 684, in _read_packet
    packet.check_error()
  File "/home/fms/project/venv/lib/python3.7/site-packages/pymysql/protocol.py", line 220, in check_error
    err.raise_mysql_exception(self._data)
  File "/home/fms/project/venv/lib/python3.7/site-packages/pymysql/err.py", line 109, in raise_mysql_exception
    raise errorclass(errno, errval)
sqlalchemy.exc.DataError: (pymysql.err.DataError) (1406, "Data too long for column '经度' at row 1")
[SQL: INSERT INTO tousu (`工单流水号`, `投诉内容`, `处理结果`, `我方办结原因`, `区县`, `乡镇`, `关联自然村_小区名`, `经度`, `纬度`, `关联基站代码`, `关联基站名称`, `投诉大类`, `投诉原因`, `网络类型`, `区域`, `区域细类`, `解决措施`, `解决措施_详`) VALUES (%(工单流水号)s, %(投诉内容)s, %(处理结果)s, %(我方办结原因)s, %(区县)s, %(乡镇)s, %(关联自然村_小区名)s, %(经度)s, %(纬度)s, %(关联基站代码)s, %(关联基站名称)s, %(投诉大类)s, %(投诉原因)s, %(网络类型)s, %(区域)s, %(区域细类)s, %(解决措施)s, %(解决措施_详)s)]
[parameters: {'工单流水号': 'TZ0000202007037857464', '投诉内容': '是否违章停机:否\r\n是否有在途单:该用户无在途单\r\n是否实名认证:是\r\nCRM用户是否停机:否\r\n计费状态:正常\r\nCRM语音功能是否开通:是\r\n位置刷新:人工操作环节\r\n用户手机终端与UIM卡是否匹配:否\r\n呼叫转移是否开通:是\r\n呼叫转移是否设置:\r\n用 ... (177 characters truncated) ... ：云南省曲靖市师宗县雄壁镇小阿舍村委会小阿舍村\r\n问题描述(故障时间\\是否有信号\\用户状态等)：用户致电手机显示2G网络，无法上网，网速慢，多次测试无效，向用户多次解释用户不认可用户对此强烈不满。\r\n用户要求："用户要求我方尽快核实处理给予回复。\r\n呼入号码：18987419302', '处理结果': '投诉产生原因：用户终端问题\r\n经过核实，用户投诉地点小阿舍村，属自然村场景，用户接收是我方师宗县雄壁镇私庄村基站信号，用户距离我方基站只有797米（详见附件地图），该基站无故障，从我方掌握的基站信息结合用户的地理位置可以判断当地覆盖正常，所以无需进行现场测试，可以判断当地4G网络信号覆盖正常，通过后台观察用户投诉时段7月3,11:00，基站在线用户数16人，平均上网速度16Mbps，可以判断当地其他用户使用正常；用户无法正常使用并非我方网络故障导致，属于用户手机终端原因导致使用不正常.建议用户重启手机再试或带手机到当地营业网点检查手机和卡。\r\n', '我方办结原因': '用户终端故障', '区县': '师宗', '乡镇': '', '关联自然村_小区名': '小阿舍村', '经度': ' 103.998857', '纬度': '24.984852', '关联基站代码': '', '关联基站名称': '', '投诉大类': None, '投诉原因': None, '网络类型': None, '区域': '农村', '区域细类': '自然村', '解决措施': '用户自行处理', '解决措施_详': None}]
(Background on this error at: http://sqlalche.me/e/13/9h9h)
[2020-07-03 23:45:16 +0800] [3008] [INFO] Handling signal: term
/home/fms/project/venv/lib/python3.7/site-packages/pymysql/cursors.py:170: Warning: (1366, "Incorrect string value: '\\xD6\\xD0\\xB9\\xFA\\xB1\\xEA...' for column 'VARIABLE_VALUE' at row 480")
  result = self._query(query)
[2020-07-03 23:45:16 +0800] [3015] [INFO] Worker exiting (pid: 3015)
[2020-07-03 23:45:16 +0800] [3020] [INFO] Worker exiting (pid: 3020)
[2020-07-03 23:45:16 +0800] [3018] [INFO] Worker exiting (pid: 3018)
/home/fms/project/venv/lib/python3.7/site-packages/pymysql/cursors.py:170: Warning: (1366, "Incorrect string value: '\\xD6\\xD0\\xB9\\xFA\\xB1\\xEA...' for column 'VARIABLE_VALUE' at row 480")
  result = self._query(query)
[2020-07-03 23:45:16 +0800] [3016] [INFO] Worker exiting (pid: 3016)
[2020-07-03 23:45:19 +0800] [3008] [INFO] Shutting down: Master
[2020-07-04 00:04:25 +0800] [2061] [INFO] Starting gunicorn 20.0.4
[2020-07-04 00:04:25 +0800] [2061] [INFO] Listening at: http://0.0.0.0:8002 (2061)
[2020-07-04 00:04:25 +0800] [2061] [INFO] Using worker: sync
[2020-07-04 00:04:25 +0800] [2066] [INFO] Booting worker with pid: 2066
[2020-07-04 00:04:25 +0800] [2069] [INFO] Booting worker with pid: 2069
[2020-07-04 00:04:25 +0800] [2071] [INFO] Booting worker with pid: 2071
[2020-07-04 00:04:25 +0800] [2072] [INFO] Booting worker with pid: 2072
[2020-07-04 00:06:13 +0800] [2061] [INFO] Handling signal: term
/home/fms/project/venv/lib/python3.7/site-packages/pymysql/cursors.py:170: Warning: (1366, "Incorrect string value: '\\xD6\\xD0\\xB9\\xFA\\xB1\\xEA...' for column 'VARIABLE_VALUE' at row 480")
  result = self._query(query)
[2020-07-04 00:06:13 +0800] [2066] [INFO] Worker exiting (pid: 2066)
[2020-07-04 00:06:13 +0800] [2071] [INFO] Worker exiting (pid: 2071)
/home/fms/project/venv/lib/python3.7/site-packages/pymysql/cursors.py:170: Warning: (1366, "Incorrect string value: '\\xD6\\xD0\\xB9\\xFA\\xB1\\xEA...' for column 'VARIABLE_VALUE' at row 480")
  result = self._query(query)
[2020-07-04 00:06:13 +0800] [2072] [INFO] Worker exiting (pid: 2072)
[2020-07-04 00:06:13 +0800] [2069] [INFO] Worker exiting (pid: 2069)
[2020-07-04 00:06:13 +0800] [2061] [INFO] Shutting down: Master
[2020-07-04 00:06:17 +0800] [2110] [INFO] Starting gunicorn 20.0.4
[2020-07-04 00:06:17 +0800] [2110] [INFO] Listening at: http://0.0.0.0:8002 (2110)
[2020-07-04 00:06:17 +0800] [2110] [INFO] Using worker: sync
[2020-07-04 00:06:17 +0800] [2116] [INFO] Booting worker with pid: 2116
[2020-07-04 00:06:17 +0800] [2117] [INFO] Booting worker with pid: 2117
[2020-07-04 00:06:17 +0800] [2119] [INFO] Booting worker with pid: 2119
[2020-07-04 00:06:17 +0800] [2122] [INFO] Booting worker with pid: 2122
[2020-07-04 09:36:13 +0800] [2110] [INFO] Handling signal: term
[2020-07-04 09:36:14 +0800] [2117] [INFO] Worker exiting (pid: 2117)
/home/fms/project/venv/lib/python3.7/site-packages/pymysql/cursors.py:170: Warning: (1366, "Incorrect string value: '\\xD6\\xD0\\xB9\\xFA\\xB1\\xEA...' for column 'VARIABLE_VALUE' at row 480")
  result = self._query(query)
[2020-07-04 09:36:14 +0800] [2122] [INFO] Worker exiting (pid: 2122)
[2020-07-04 09:36:14 +0800] [2119] [INFO] Worker exiting (pid: 2119)
[2020-07-04 09:36:14 +0800] [2116] [INFO] Worker exiting (pid: 2116)
